Workbook

Sheet Hypothesis Tests
A1: Task 5 – Statistical Validation
A2: Hypothesis 1 – Win Rate Comparison
A3: H₀ (Null Hypothesis): | B3: Product-Led Signup + Inbound Organic deals do not have a higher win rate than Cold Outreach + Paid Search deals.
A5: H₁ (Alternative Hypothesis): | B5: Product-Led Signup + Inbound Organic deals have a higher win rate than Cold Outreach + Paid Search deals.
A7: Test: | B7: Two-Proportion Z-Test
A9: Confidence Level: | B9: 0.95
A11: Significance Level (α): | B11: 0.05
A14: Group | B14: Won | C14: Lost | D14: Closed Deals | E14: Win Rate
A15: Product-Led Signup + Inbound Organic | B15: 158 | C15: 119 | D15: =B15+C15 -> 277 | E15: =B15/D15 -> 0.57039711
A16: Cold Outreach + Paid Search | B16: 163 | C16: 152 | D16: =B16+C16 -> 315 | E16: =B16/D16 -> 0.51746032
A18: Pooled Win Rate | B18: =(B15+B16)/(D15+D16) -> 0.54222973
A19: Standard Error | B19: =SQRT(B18*(1-B18)*(1/D15+1/D16)) -> 0.041037524
A20: Z-Statistic | B20: =(E15-E16)/B19 -> 1.2899607
A21: One-Tailed P-Value | B21: =1-_xlfn.NORM.S.DIST(B20,TRUE) -> 0.098532145
A22: Decision | B22: =IF(B21<B11,"Reject H0","Fail to Reject H0") -> Fail to Reject H0
A24: Business Interpretation: | B24: Although Product-Led Signup + Inbound Organic had a higher observed win rate (57.04% vs. 51.75%), the difference is not statistically significant (p = 0.099 > 0.05). Therefore, there is not enough evidence to conclude that these channels have a higher win rate.
A27: Hypothesis 2 – LTV/CAC Comparison
A29: H₀ (Null Hypothesis): | B29: The mean LTV/CAC ratio is the same across all acquisition channels.
A30: H₁ (Alternative Hypothesis): | B30: At least one acquisition channel has a different mean LTV/CAC ratio.
A31: Test: | B31: One-Way ANOVA
A32: Confidence Level: | B32: 0.95
A33: Significance Level (α): | B33: 0.05
A37: Anova: Single Factor
A39: SUMMARY
A40: Groups | B40: Count | C40: Sum | D40: Average | E40: Variance
A41: Product-Led Signup | B41: 143 | C41: 253763.52 | D41: 1774.5701 | E41: 1866592.9
A42: Inbound Organic | B42: 169 | C42: 155221.12 | D42: 918.46817 | E42: 549954.68
A43: Webinar | B43: 137 | C43: 67312.32 | D43: 491.3308 | E43: 152373.7
A44: Partner Referral | B44: 137 | C44: 52959.95 | D44: 386.56898 | E44: 96986.407
A45: Cold Outreach | B45: 147 | C45: 45511.4 | D45: 309.60136 | E45: 62332.778
A46: Paid Search | B46: 122 | C46: 31436.36 | D46: 257.67508 | E46: 44953.233
A47: LinkedIn Ads | B47: 139 | C47: 28727.43 | D47: 206.67216 | E47: 24091.831
A50: ANOVA
A51: Source of Variation | B51: SS | C51: df | D51: MS | E51: F | F51: P-value | G51: F crit
A52: Between Groups | B52: 2.6898781e+08 | C52: 6 | D52: 44831301 | E52: 108.12724 | F52: 1.0280954e-104 | G52: 2.1077505
A53: Within Groups | B53: 4.0922615e+08 | C53: 987 | D53: 414616.16
A55: Total | B55: 6.7821396e+08 | C55: 993
A58: ANOVA Assumption Check
A59: Variance Equality | B59: Unequal variances (Levene p < 0.001) | C59: =MEDIAN(H2_ANOVA_Data!V2:V144) -> 1401.53 | D59: =MEDIAN(H2_ANOVA_Data!W2:W170) -> 731.3 | E59: =MEDIAN(H2_ANOVA_Data!X2:X138) -> 405.35 | F59: =MEDIAN(H2_ANOVA_Data!Y2:Y138) -> 314.73 | G59: =MEDIAN(H2_ANOVA_Data!Z2:Z148) -> 238.63 | H59: =MEDIAN(H2_ANOVA_Data!AA2:AA123) -> 204.955 | I59: =MEDIAN(H2_ANOVA_Data!AB2:AB140) -> 173.09
A60: Normality / Distribution | B60: Strongly right-skewed; normality assumption is questionable
...

Sheet H2_ANOVA_Data
A1: Record_ID | B1: Customer_ID | C1: Cohort | D1: Service_Line | E1: Acquisition_Channel | F1: Scenario | G1: MRR_USD | H1: ARR_USD | I1: CAC_USD | J1: LTV_USD | K1: LTV_CAC_Ratio | L1: Monthly_Churn_Rate_Pct | M1: Expansion_MRR_USD | N1: Contraction_MRR_USD | O1: Burn_Rate_USD | P1: Cash_Balance_USD | Q1: Runway_Months | R1: Gross_Margin_Pct | S1: Budget_Variance_Pct | T1: Period_Start_Date | U1: Period_End_Date | V1: Product-Led Signup | W1: Inbound Organic | X1: Webinar | Y1: Partner Referral | Z1: Cold Outreach | AA1: Paid Search | AB1: LinkedIn Ads | AC1: Product-Led Signup | AD1: Inbound Organic | AE1: Webinar | AF1: Partner Referral | AG1: Cold Outreach | AH1: Paid Search | AI1: LinkedIn Ads
A2: FIN-0001 | B2: CUST-0712 | C2: 2023-Q2 | D2: WorkHub Enterprise | E2: Webinar | F2: Optimistic | G2: 7113.63 | H2: 85363.56 | I2: 253.1 | J2: 251970.96 | K2: 995.54 | L2: 6.58 | M2: 52.12 | N2: 0 | O2: 343848.6 | P2: 19239355 | Q2: 56 | R2: 78.09 | S2: 6.98 | T2: 2022-04-10 | U2: 2022-05-15 | V2: {=_xlfn._xlws.FILTER($K$2:$K$1101,($E$2:$E$1101=V$1)*($I$2:$I$1101<>"")*($J$2:$J$1101<>"")*($K$2:$K$1101<>"")*($K$2:$K$1101>=0),"")} -> 557.48 | W2: {=_xlfn._xlws.FILTER($K$2:$K$1101,($E$2:$E$1101=W$1)*($I$2:$I$1101<>"")*($J$2:$J$1101<>"")*($K$2:$K$1101<>"")*($K$2:$K$1101>=0),"")} -> 467 | X2: {=_xlfn._xlws.FILTER($K$2:$K$1101,($E$2:$E$1101=X$1)*($I$2:$I$1101<>"")*($J$2:$J$1101<>"")*($K$2:$K$1101<>"")*($K$2:$K$1101>=0),"")} -> 995.54 | Y2: {=_xlfn._xlws.FILTER($K$2:$K$1101,($E$2:$E$1101=Y$1)*($I$2:$I$1101<>"")*($J$2:$J$1101<>"")*($K$2:$K$1101<>"")*($K$2:$K$1101>=0),"")} -> 122.87 | Z2: {=_xlfn._xlws.FILTER($K$2:$K$1101,($E$2:$E$1101=Z$1)*($I$2:$I$1101<>"")*($J$2:$J$1101<>"")*($K$2:$K$1101<>"")*($K$2:$K$1101>=0),"")} -> 155.17 | AA2: {=_xlfn._xlws.FILTER($K$2:$K$1101,($E$2:$E$1101=AA$1)*($I$2:$I$1101<>"")*($J$2:$J$1101<>"")*($K$2:$K$1101<>"")*($K$2:$K$1101>=0),"")} -> 279.82 | AB2: {=_xlfn._xlws.FILTER($K$2:$K$1101,($E$2:$E$1101=AB$1)*($I$2:$I$1101<>"")*($J$2:$J$1101<>"")*($K$2:$K$1101<>"")*($K$2:$K$1101>=0),"")} -> 234.03 | AC2: 844.05 | AD2: 264.3 | AE2: 590.19 | AF2: 191.86 | AG2: 83.46 | AH2: 74.865 | AI2: 60.94
A3: FIN-0002 | B3: CUST-1099 | C3: 2024-Q2 | D3: API Access | E3: Cold Outreach | F3: Optimistic | G3: 15000.1 | H3: 180001.2 | I3: 589.51 | J3: 91476.66 | K3: 155.17 | L3: 53.17 | M3: 2947.43 | N3: 0 | O3: 622565.27 | P3: 17374897 | Q3: 27.9 | R3: 55.54 | S3: -26.66 | T3: 2023-06-08 | U3: 2023-08-13 | V3: 910.35 | W3: 124.75 | X3: 128.03 | Y3: 337.06 | Z3: 85.18 | AA3: 221.1 | AB3: 90.12 | AC3: 491.18 | AD3: 606.55 | AE3: 277.32 | AF3: 22.33 | AG3: 153.45 | AH3: 16.145 | AI3: 82.97
A4: FIN-0003 | B4: CUST-1110 | C4: 2024-Q4 | D4: API Access | E4: Paid Search | F4: Optimistic | G4: 9439.01 | H4: 113268.12 | I4: 651.79 | J4: 182382.51 | K4: 279.82 | L4: 6.06 | M4: 0 | N4: 1229.11 | O4: 832270.77 | P4: 17697570 | Q4: 21.3 | R4: 75.11 | S4: 128.11 | T4: 2022-11-23 | U4: 2022-12-30 | V4: 3869.04 | W4: 1659.74 | X4: 1209.53 | Y4: 374.9 | Z4: 33.74 | AA4: 287.93 | AB4: 56.8 | AC4: 2467.51 | AD4: 928.44 | AE4: 804.18 | AF4: 60.17 | AG4: 204.89 | AH4: 82.975 | AI4: 116.29
A5: FIN-0004 | B5: CUST-1349 | C5: 2022-Q3 | D5: WorkHub Pro | E5: Product-Led Signup | F5: Pessimistic | G5: 5601.95 | H5: 67223.4 | I5: 148.92 | J5: 83020.66 | K5: 557.48 | L5: 2.94 | M5: 0 | N5: 0 | O5: 645226.89 | P5: 13541223 | Q5: 21 | R5: 72.22 | S5: 24 | T5: 2024-05-29 | U5: 2024-08-06 | V5: 2264.6 | W5: 590.52 | X5: 78.28 | Y5: 365.85 | Z5: 278.76 | AA5: 398.97 | AB5: 248.34 | AC5: 863.07 | AD5: 140.78 | AE5: 327.07 | AF5: 51.12 | AG5: 40.13 | AH5: 194.015 | AI5: 75.25
A6: FIN-0005 | B6: CUST-0073 | C6: 2022-Q3 | D6: WorkHub Pro | E6: Inbound Organic | F6: Pessimistic | G6: 1862.58 | H6: 22350.96 | I6: 129.42 | J6: 60438.76 | K6: 467 | L6: 1.56 | M6: 0 | N6: 208.31 | O6: 246750.63 | P6: 22808993 | Q6: 92.4 | R6: 73.04 | S6: 21.48 | T6: 2024-01-22 | U6: 2024-03-08 | V6: 1049.61 | W6: 457.96 | X6: 1489.4 | Y6: 272.65 | Z6: 625.8 | AA6: 111.23 | AB6: 49.35 | AC6: 351.92 | AD6: 273.34 | AE6: 1084.05 | AF6: 42.08 | AG6: 387.17 | AH6: 93.725 | AI6: 123.74
A7: FIN-0006 | B7: CUST-0447 | C7: 2022-Q4 | D7: WorkHub Pro | E7: Inbound Organic | F7: Base | G7: 10385.63 | H7: 124627.56 | I7: 243.86 | J7: 365196.36 | L7: 7.78 | M7: 0 | N7: 0 | O7: 676775.72 | P7: 1678992.8 | Q7: 2.5 | R7: 78.79 | S7: 9.7 | T7: 2024-03-08 | U7: 2024-04-30 | V7: 2462.23 | W7: 2749.23 | X7: 46.13 | Y7: 26.43 | Z7: 101.33 | AA7: 52.94 | AB7: 323.99 | AC7: 1060.7 | AD7: 2017.93 | AE7: 359.22 | AF7: 288.3 | AG7: 137.3 | AH7: 152.015 | AI7: 150.9
A8: FIN-0007 | B8: CUST-1084 | C8: 2022-Q3 | D8: WorkHub Enterprise | E8: LinkedIn Ads | F8: Base | G8: 9546.76 | H8: 114561.12 | I8: 875.81 | J8: 204966.82 | K8: 234.03 | L8: 2.22 | M8: 2995.36 | N8: 456.95 | O8: 327811.8 | P8: 22740840 | Q8: 69.4 | R8: 79.65 | S8: -5.27 | T8: 2023-12-18 | U8: 2024-03-05 | V8: 989.7 | W8: 1458.38 | X8: 316.12 | Y8: 597.67 | Z8: 124.84 | AA8: 184.76 | AB8: 593.33 | AC8: 411.83 | AD8: 727.08 | AE8: 89.23 | AF8: 282.94 | AG8: 113.79 | AH8: 20.195 | AI8: 420.24
A9: FIN-0008 | B9: CUST-0237 | C9: 2024-Q2 | D9: WorkHub Pro | E9: Cold Outreach | F9: Pessimistic | G9: 9060.92 | H9: 108731.04 | I9: 430.09 | J9: 84562.82 | K9: -196.62 | L9: 52.17 | M9: 510.84 | N9: 0 | O9: 659347.52 | P9: 8135544.3 | Q9: 12.3 | R9: 76.16 | S9: 39.09 | T9: 2022-04-22 | U9: 2022-06-22 | V9: 1465 | W9: 46.08 | X9: 507.94 | Y9: 206.5 | Z9: 373.7 | AA9: 70.33 | AB9: 51.83 | AC9: 63.47 | AD9: 685.22 | AE9: 102.59 | AF9: 108.23 | AG9: 135.07 | AH9: 134.625 | AI9: 121.26
A10: FIN-0009 | B10: CUST-1344 | C10: 2023-Q1 | D10: WorkHub Core | E10: Webinar | F10: Pessimistic | G10: 5275.89 | H10: 63310.68 | I10: 470.36 | J10: 60218.87 | K10: 128.03 | L10: 9.74 | M10: 630.57 | N10: 56.33 | O10: 508790.47 | P10: 4743902.5 | Q10: 9.3 | R10: 70.5 | S10: 35.62 | T10: 2022-07-28 | U10: 30/09/2022 | V10: 2185.03 | W10: 385.3 | X10: 616.89 | Y10: 2.12 | Z10: 508.58 | AA10: 397.78 | AB10: 153.13 | AC10: 783.5 | AD10: 346 | AE10: 211.54 | AF10: 312.61 | AG10: 269.95 | AH10: 192.825 | AI10: 19.96
A11: FIN-0010 | B11: CUST-1213 | C11: 2024-Q3 | D11: WorkHub Pro | E11: Cold Outreach | F11: Base | G11: 7491.05 | H11: 89892.6 | I11: 702.58 | J11: 59845.71 | K11: 85.18 | L11: 11.1 | M11: 650.39 | N11: 0 | O11: 828711.77 | P11: 21544627 | Q11: 26 | R11: 81.13 | S11: -28.21 | T11: 2022-06-09 | U11: 2022-08-25 | V11: 1140.24 | W11: 1006.28 | X11: 37.33 | Y11: 108.69 | Z11: 1002.46 | AA11: 105.28 | AB11: 330.21 | AC11: 261.29 | AD11: 274.98 | AE11: 368.02 | AF11: 206.04 | AG11: 763.83 | AH11: 99.675 | AI11: 157.12
A12: FIN-0011 | B12: CUST-0701 | C12: 2024-Q2 | D12: WorkHub Pro | E12: Cold Outreach | F12: Base | G12: 851.27 | H12: 10215.24 | I12: 735.6 | J12: 24822.02 | K12: 33.74 | L12: 11.04 | M12: 0 | N12: 0 | O12: 853289.81 | P12: 11970922 | Q12: 14 | R12: 78.4 | S12: -15.69 | T12: 2023-01-06 | U12: 17/02/2023 | V12: 2056.63 | W12: 2188.34 | X12: 993.49 | Y12: 140.93 | Z12: 223.89 | AA12: 226.15 | AB12: 312.7 | AC12: 655.1 | AD12: 1457.04 | AE12: 588.14 | AF12: 173.8 | AG12: 14.74 | AH12: 21.195 | AI12: 139.61
A13: FIN-0012 | B13: CUST-0389 | C13: 2024-Q2 | D13: WorkHub Pro | E13: Webinar | F13: Optimistic | G13: 15497.5 | H13: 185970 | I13: 435.4 | J13: 526630.55 | K13: 1209.53 | L13: 8.31 | M13: 0 | N13: 0 | O13: 245993.77 | P13: 18344697 | Q13: 74.6 | R13: 75.97 | S13: -16.2 | T13: 2023-09-20 | U13: 2023-11-19 | V13: 161.62 | W13: 1583.11 | X13: 114.46 | Y13: 130.1 | Z13: 418.58 | AA13: 623.42 | AB13: 343.11 | AC13: 1239.91 | AD13: 851.81 | AE13: 290.89 | AF13: 184.63 | AG13: 179.95 | AH13: 418.465 | AI13: 170.02
A14: FIN-0013 | B14: CUST-0851 | C14: 2022-Q2 | D14: Analytics Add-on | E14: Inbound Organic | F14: Pessimistic | G14: 895.38 | H14: 10744.56 | I14: 236.97 | J14: 29562.37 | K14: 124.75 | L14: 11.14 | M14: 68.19 | N14: 0 | O14: 860962.14 | P14: 14815813 | Q14: 17.2 | R14: 80.26 | S14: 17.59 | T14: 2022-07-27 | U14: 2022-09-18 | V14: 459.75 | W14: 497.84 | X14: 405.35 | Y14: 179.6 | Z14: 177.35 | AA14: 72.84 | AB14: 226.62 | AC14: 941.78 | AD14: 233.46 | AE14: 0 | AF14: 135.13 | AG14: 61.28 | AH14: 132.115 | AI14: 53.53
A15: FIN-0014 | B15: CUST-1413 | C15: 2022-Q3 | D15: WorkHub Pro | E15: Cold Outreach | F15: Pessimistic | G15: 5575.79 | H15: 66909.48 | I15: 573.34 | J15: 159823.55 | K15: 278.76 | L15: 8.57 | M15: 1555.84 | N15: 0 | O15: 603892.7 | P15: 10968489 | Q15: 18.2 | R15: 76.79 | S15: 29.03 | T15: 2022-11-09 | U15: 2022-12-17 | V15: 1355.08 | W15: 2385.37 | X15: 187.35 | Y15: 210.77 | Z15: 106.4 | AA15: 181.11 | AB15: 180.01 | AC15: 46.45 | AD15: 1654.07 | AE15: 218 | AF15: 103.96 | AG15: 132.23 | AH15: 23.845 | AI15: 6.92
A16: FIN-0015 | B16: CUST-0822 | C16: 2023-Q3 | D16: API Access | E16: Product-Led Signup | F16: Base | G16: 4437.82 | H16: 53253.84 | I16: 112.75 | J16: 102641.61 | K16: 910.35 | L16: 11.71 | M16: 0 | N16: 0 | O16: 779065.88 | P16: 20163204 | Q16: 25.9 | R16: 58.48 | S16: -34.46 | T16: 2023-03-02 | U16: 2023-05-09 | V16: 2705.72 | W16: 1010.99 | X16: 786.77 | Y16: 1112.29 | Z16: 33.2 | AA16: 176.77 | AB16: 250.77 | AC16: 1304.19 | AD16: 279.69 | AE16: 381.42 | AF16: 797.56 | AG16: 205.43 | AH16: 28.185 | AI16: 77.68
A17: FIN-0016 | B17: CUST-0940 | C17: 2023-Q1 | D17: Analytics Add-on | E17: Partner Referral | F17: Base | G17: 1815.61 | H17: 21787.32 | I17: 364.56 | J17: 44794.74 | K17: 122.87 | L17: 3.93 | M17: 468.76 | N17: 0 | O17: 197096.07 | P17: 702560.57 | R17: 76.72 | S17: 42.55 | T17: 2024-02-27 | U17: 2024-04-23 | V17: 2613.32 | W17: 3456.92 | X17: 855.92 | Y17: 1190.6 | Z17: 512.91 | AA17: 605.57 | AB17: 56.53 | AC17: 1211.79 | AD17: 2725.62 | AE17: 450.57 | AF17: 875.87 | AG17: 274.28 | AH17: 400.615 | AI17: 116.56
A18: FIN-0017 | B18: CUST-1432 | C18: 2025-Q1 | D18: API Access | E18: Partner Referral | F18: Base | G18: 5321.82 | H18: 63861.84 | I18: 495.6 | J18: 120485.97 | K18: -243.11 | L18: 5.41 | M18: 742.93 | N18: 0 | O18: 591929.99 | P18: 5921593.8 | Q18: 10 | R18: 72.38 | S18: 7.52 | T18: 2024-06-05 | U18: 2024-07-28 | V18: 669.28 | W18: 1386.45 | X18: 97.17 | Y18: 308.37 | Z18: 455.35 | AA18: 400.3 | AB18: 115.02 | AC18: 732.25 | AD18: 655.15 | AE18: 308.18 | AF18: 6.36 | AG18: 216.72 | AH18: 195.345 | AI18: 58.07
A19: FIN-0018 | B19: CUST-1414 | C19: 2023-Q4 | D19: Analytics Add-on | E19: Partner Referral | F19: Base | G19: 4988.93 | H19: 59867.16 | I19: 427.31 | J19: 144029.93 | K19: 337.06 | L19: 32.88 | M19: 1533.1 | N19: 0 | O19: 308799.03 | P19: 19720929 | Q19: 63.9 | R19: 72.44 | S19: -2.18 | T19: 2022-02-17 | U19: 2022-05-01 | V19: 3621.26 | W19: 930.46 | X19: 94.66 | Y19: 109.29 | Z19: 35.33 | AA19: 50.79 | AB19: 444.46 | AC19: 2219.73 | AD19: 199.16 | AE19: 310.69 | AF19: 205.44 | AG19: 203.3 | AH19: 154.165 | AI19: 271.37
A20: FIN-0019 | B20: CUST-1014 | C20: 2022-Q2 | D20: WorkHub Enterprise | E20: Inbound Organic | F20: Base | G20: 9541.85 | H20: 114502.2 | I20: 159.32 | J20: 132143.04 | L20: 3.37 | M20: 0 | N20: 0 | O20: 284518.26 | P20: 14629896 | Q20: 51.4 | R20: 72 | S20: 34.84 | T20: 2022-10-15 | U20: 2022-12-17 | V20: 1941.74 | W20: 456.66 | X20: 15.01 | Y20: 318.04 | Z20: 333.54 | AA20: 202.29 | AB20: 29.82 | AC20: 540.21 | AD20: 274.64 | AE20: 390.34 | AF20: 3.31 | AG20: 94.91 | AH20: 2.665 | AI20: 143.27
A21: FIN-0020 | B21: CUST-1426 | C21: 2022-Q4 | D21: API Access | E21: Partner Referral | F21: Optimistic | G21: 9053.25 | H21: 108639 | I21: 583.37 | J21: 218704.05 | K21: 374.9 | L21: 9.28 | M21: 713.19 | N21: 0 | O21: 289950.19 | P21: 16675600 | Q21: 57.5 | R21: 67.19 | S21: -5.04 | T21: 2023-12-10 | U21: 15/02/2024 | V21: 2069.57 | W21: 927.14 | X21: 735.12 | Y21: 303.33 | Z21: 887.14 | AA21: 570.27 | AB21: 646.91 | AC21: 668.04 | AD21: 195.84 | AE21: 329.77 | AF21: 11.4 | AG21: 648.51 | AH21: 365.315 | AI21: 473.82
A22: FIN-0021 | B22: CUST-0368 | C22: 2023-Q1 | D22: Analytics Add-on | E22: Paid Search | F22: Optimistic | G22: 8211.66 | H22: 98539.92 | I22: 540.05 | J22: 119403.83 | K22: 221.1 | L22: 3.77 | M22: 1514.7 | N22: 0 | O22: 768244.55 | P22: 23659607 | Q22: 30.8 | R22: 78.31 | S22: -22.92 | T22: 2024-05-25 | U22: 27/07/2024 | V22: 722.36 | W22: 178.31 | X22: 246.06 | Y22: 434.55 | Z22: 87.21 | AA22: 135.94 | AB22: 470.65 | AC22: 679.17 | AD22: 552.99 | AE22: 159.29 | AF22: 119.82 | AG22: 151.42 | AH22: 69.015 | AI22: 297.56
A23: FIN-0022 | B23: CUST-0411 | C23: 2022-Q3 | D23: WorkHub Core | E23: Cold Outreach | F23: Pessimistic | G23: 16864.1 | H23: 202369.2 | I23: 677.02 | J23: 423679.28 | K23: 625.8 | L23: 5.76 | M23: 4877.79 | N23: 0 | O23: 664242.58 | P23: 1828201 | Q23: 2.8 | R23: 74.58 | S23: 20.36 | T23: 2023-09-09 | U23: 2023-11-09 | V23: 1205.92 | W23: 2179.79 | X23: 1252 | Y23: 103.34 | Z23: 273.92 | AA23: 271.95 | AB23: 504.66 | AC23: 195.61 | AD23: 1448.49 | AE23: 846.65 | AF23: 211.39 | AG23: 35.29 | AH23: 66.995 | AI23: 331.57
A24: FIN-0023 | B24: CUST-0201 | C24: 2023-Q2 | D24: WorkHub Core | E24: Product-Led Signup | F24: Optimistic | G24: 17629.52 | H24: 211554.24 | I24: 139.08 | J24: 538105.58 | K24: 3869.04 | L24: 1.82 | M24: 454.05 | N24: 1744.64 | O24: 687265.01 | P24: 8302248.3 | R24: 66.37 | S24: 6.64 | T24: 2022-11-05 | U24: 2023-01-19 | V24: 1961.63 | W24: 408.17 | X24: 244.55 | Y24: 120.05 | Z24: 128.83 | AA24: 18.03 | AB24: 119.83 | AC24: 560.1 | AD24: 323.13 | AE24: 160.8 | AF24: 194.68 | AG24: 109.8 | AH24: 186.925 | AI24: 53.26
A25: FIN-0024 | B25: CUST-1319 | C25: 2022-Q3 | D25: Analytics Add-on | E25: Webinar | F25: Base | G25: 1882.93 | H25: 22595.16 | I25: 535.76 | J25: 41940.12 | K25: 78.28 | L25: 2.16 | M25: 0 | N25: 0 | O25: 463287.36 | P25: 22007196 | Q25: 47.5 | R25: 57.06 | S25: -12.03 | T25: 2022-02-18 | U25: 14/05/2022 | V25: 64.01 | W25: 40.85 | X25: 308.59 | Y25: 1063.31 | Z25: 95.6 | AA25: 220.5 | AB25: 154.83 | AC25: 1337.52 | AD25: 690.45 | AE25: 96.76 | AF25: 748.58 | AG25: 143.03 | AH25: 15.545 | AI25: 18.26
A26: FIN-0025 | B26: CUST-0330 | C26: 2024-Q4 | D26: WorkHub Core | E26: Inbound Organic | F26: Pessimistic | G26: 12258.83 | H26: 147105.96 | I26: 180.1 | J26: 298919.48 | K26: 1659.74 | L26: 5.25 | M26: 3037.24 | N26: 0 | O26: 922575.87 | P26: 21497432 | Q26: 23.3 | R26: 62.79 | S26: 19.47 | T26: 2024-06-30 | U26: 2024-08-27 | V26: 2221.5 | W26: 317.34 | X26: 384.85 | Y26: 215.99 | Z26: 1122.76 | AA26: 174.72 | AB26: 2.52 | AC26: 819.97 | AD26: 413.96 | AE26: 20.5 | AF26: 98.74 | AG26: 884.13 | AH26: 30.235 | AI26: 170.57
A27: FIN-0026 | B27: CUST-1492 | C27: 2022-Q1 | D27: API Access | E27: Product-Led Signup | F27: Pessimistic | G27: 16803.09 | H27: 201637.08 | I27: 101.92 | J27: 248980.83 | L27: 2 | M27: 751.33 | N27: 2509.24 | O27: 459579.31 | P27: 1064102.4 | Q27: 2.3 | R27: 61.7 | S27: -4.75 | T27: 2024-05-20 | U27: 2024-07-31 | V27: 1581.08 | W27: 2219.54 | X27: 1656.87 | Y27: 208.68 | Z27: 418.84 | AA27: 49.18 | AB27: 203.43 | AC27: 179.55 | AD27: 1488.24 | AE27: 1251.52 | AF27: 106.05 | AG27: 180.21 | AH27: 155.775 | AI27: 30.34
A28: FIN-0027 | B28: CUST-0752 | C28: 2022-Q1 | D28: API Access | E28: LinkedIn Ads | F28: Optimistic | G28: 11131.3 | H28: 133575.6 | I28: 1160.55 | J28: 104589.11 | K28: 90.12 | L28: 3.14 | M28: 1311.78 | N28: 657.22 | O28: 183782.27 | P28: 8069544.9 | Q28: 43.9 | R28: 77.76 | S28: 37.11 | T28: 2022-04-27 | U28: 2022-06-06 | V28: 1431.68 | W28: 376.63 | X28: 144.04 | Y28: 780.51 | Z28: 116.17 | AA28: 88.85 | AB28: 595.96 | AC28: 30.15 | AD28: 354.67 | AE28: 261.31 | AF28: 465.78 | AG28: 122.46 | AH28: 116.105 | AI28: 422.87
A29: FIN-0028 | B29: CUST-1077 | C29: 2024-Q3 | D29: WorkHub Core | E29: Paid Search | F29: Optimistic | G29: 9015.44 | H29: 108185.28 | I29: 966.12 | J29: 278171.77 | K29: 287.93 | L29: 1.83 | M29: 0 | N29: 1739.96 | O29: 776905.7 | P29: 1686770.2 | Q29: 2.2 | R29: 73.33 | S29: 17.78 | T29: 2023-02-16 | U29: 2023-04-30 | V29: 213.78 | W29: 821.85 | X29: 17.74 | Y29: 26.28 | Z29: 211.26 | AA29: 203.7 | AB29: 186.11 | AC29: 1187.75 | AD29: 90.55 | AE29: 387.61 | AF29: 288.45 | AG29: 27.37 | AH29: 1.255 | AI29: 13.02
A30: FIN-0029 | B30: CUST-1447 | C30: 2024-Q2 | D30: WorkHub Enterprise | E30: LinkedIn Ads | F30: Pessimistic | G30: 5412.71 | H30: 64952.52 | I30: 985.9 | J30: 55996.67 | K30: 56.8 | L30: 7.41 | M30: 664.22 | N30: 0 | O30: 265177.25 | P30: 10241995 | Q30: 38.6 | R30: 58.44 | S30: 58.61 | T30: 2022-11-26 | U30: 2023-01-14 | V30: 1559.15 | W30: 834.28 | X30: 82.54 | Y30: 655.98 | Z30: 176.42 | AA30: 101.09 | AB30: 600.21 | AC30: 157.62 | AD30: 102.98 | AE30: 322.81 | AF30: 341.25 | AG30: 62.21 | AH30: 103.865 | AI30: 427.12
A31: FIN-0030 | B31: CUST-1431 | C31: 2022-Q3 | D31: Analytics Add-on | E31: Webinar | F31: Pessimistic | G31: 17945.13 | H31: 215341.56 | I31: 406.14 | J31: 604905.19 | K31: 1489.4 | L31: 4.62 | M31: 0 | N31: 0 | O31: 659760.04 | P31: 12425999 | Q31: 18.8 | R31: 77.13 | S31: -10.64 | T31: 2022-07-26 | U31: 2022-10-07 | V31: 2572.82 | W31: 1088.2 | X31: 212.09 | Y31: 574.79 | Z31: 688.68 | AA31: 525.42 | AB31: 308.85 | AC31: 1171.29 | AD31: 356.9 | AE31: 193.26 | AF31: 260.06 | AG31: 450.05 | AH31: 320.465 | AI31: 135.76
A32: FIN-0031 | B32: CUST-1407 | C32: 2022-Q1 | D32: WorkHub Core | E32: Partner Referral | F32: Base | G32: 14311.18 | H32: 171734.16 | I32: 611.2 | J32: 223610.52 | K32: 365.85 | L32: 9.86 | M32: 0 | N32: 1748.14 | O32: 793865.09 | P32: 3039146.9 | Q32: 3.8 | R32: 59.82 | S32: 54.26 | T32: 2022-11-11 | U32: 2022-12-28 | V32: 1345.55 | W32: 1492.18 | X32: 1272.07 | Y32: 384.35 | Z32: 255.68 | AA32: 569.39 | AB32: 655.44 | AC32: 55.98 | AD32: 760.88 | AE32: 866.72 | AF32: 69.62 | AG32: 17.05 | AH32: 364.435 | AI32: 482.35
A33: FIN-0032 | B33: CUST-1121 | C33: 2022-Q4 | D33: WorkHub Pro | E33: Product-Led Signup | F33: Optimistic | G33: 17491.21 | H33: 209894.52 | I33: 111.94 | J33: 253499.86 | K33: 2264.6 | L33: 6.35 | M33: 825.73 | N33: 0 | O33: 836855.78 | P33: 9340990.8 | Q33: 11.2 | R33: 63.15 | S33: -24.96 | T33: 02/07/2024 | U33: 2024-09-13 | V33: 721.9 | W33: 732.02 | X33: 329.23 | Y33: 421.02 | Z33: 232.46 | AA33: 118.96 | AB33: 139.51 | AC33: 679.63 | AD33: 0.72 | AE33: 76.12 | AF33: 106.29 | AG33: 6.17 | AH33: 85.995 | AI33: 33.58
A34: FIN-0033 | B34: CUST-1371 | C34: 2022-Q3 | D34: Analytics Add-on | E34: Product-Led Signup | F34: Base | G34: 5494.88 | H34: 65938.56 | I34: 102.59 | J34: 107679.71 | K34: 1049.61 | L34: 4.58 | M34: 0 | N34: 0 | O34: 508599.64 | P34: 12598498 | Q34: 24.8 | R34: 71.94 | S34: 154.57 | T34: 2023-10-31 | U34: 2024-01-07 | V34: 2984.77 | W34: 93.48 | X34: 586.63 | Y34: 31.37 | Z34: 203.95 | AA34: 274 | AB34: 6.17 | AC34: 1583.24 | AD34: 637.82 | AE34: 181.28 | AF34: 283.36 | AG34: 34.68 | AH34: 69.045 | AI34: 166.92
A35: FIN-0034 | B35: CUST-1438 | C35: 2022-Q1 | D35: Analytics Add-on | E35: Cold Outreach | F35: Optimistic | G35: 10560.95 | H35: 126731.4 | I35: 700.59 | J35: 70994.18 | K35: 101.33 | L35: 11.7 | M35: 1265.04 | N35: 1431.23 | O35: 720930.67 | P35: 6840180.1 | Q35: 9.5 | R35: 74.37 | S35: 28.28 | T35: 2023-02-23 | U35: 2023-05-23 | V35: 3188.62 | W35: 597.14 | X35: 100.2 | Y35: 220.85 | Z35: 122.69 | AA35: 89.22 | AB35: 11.74 | AC35: 1787.09 | AD35: 134.16 | AE35: 305.15 | AF35: 93.88 | AG35: 115.94 | AH35: 115.735 | AI35: 161.35
A36: FIN-0035 | B36: CUST-0408 | C36: 2022-Q4 | D36: WorkHub Pro | E36: Partner Referral | F36: Pessimistic | G36: 4372.29 | H36: 52467.48 | I36: 308.95 | J36: 84234.29 | K36: 272.65 | L36: 6.39 | M36: 1156.21 | N36: 328.4 | O36: 936320.17 | P36: 17318191 | Q36: 18.5 | R36: -40.13 | S36: -38.5 | T36: 2022-12-15 | U36: 2023-01-28 | V36: 794.88 | W36: 1863.85 | X36: 192.32 | Y36: 164 | Z36: 583.53 | AA36: 450.46 | AB36: 224.89 | AC36: 606.65 | AD36: 1132.55 | AE36: 213.03 | AF36: 150.73 | AG36: 344.9 | AH36: 245.505 | AI36: 51.8
A37: FIN-0036 | B37: CUST-0203 | C37: 2023-Q2 | D37: WorkHub Core | E37: Webinar | F37: Pessimistic | G37: 729.49 | H37: 8753.88 | I37: 353.03 | J37: 16286.84 | K37: 46.13 | L37: 2.42 | M37: 66.16 | N37: 0 | O37: 281667.75 | P37: 20032956 | Q37: 71.1 | R37: 55.46 | S37: -27.16 | T37: 2024-03-27 | U37: 2024-06-13 | V37: 2561.83 | W37: 216.82 | X37: 468.82 | Y37: 22.76 | Z37: 145.81 | AA37: 62.97 | AB37: 87.02 | AC37: 1160.3 | AD37: 514.48 | AE37: 63.47 | AF37: 291.97 | AG37: 92.82 | AH37: 141.985 | AI37: 86.07
A38: FIN-0037 | B38: CUST-0238 | C38: 2024-Q4 | D38: Analytics Add-on | E38: LinkedIn Ads | F38: Base | G38: 11972.67 | H38: 143672.04 | I38: 1180.66 | J38: 293204.98 | K38: 248.34 | L38: 9.39 | M38: 4159.69 | N38: 1455.97 | O38: 798837 | P38: 16114380 | Q38: 20.2 | R38: 70.99 | S38: -35.13 | T38: 2023-08-17 | U38: 2023-11-03 | V38: 250.57 | W38: 31.6 | X38: 481.65 | Y38: 867.91 | Z38: 248.31 | AA38: 339.92 | AB38: 133.77 | AC38: 1150.96 | AD38: 699.7 | AE38: 76.3 | AF38: 553.18 | AG38: 9.68 | AH38: 134.965 | AI38: 39.32
A39: FIN-0038 | B39: CUST-0516 | C39: 2024-Q3 | D39: Analytics Add-on | E39: Inbound Organic | F39: Optimistic | G39: 6101.88 | H39: 73222.56 | I39: 214.34 | J39: 126571.64 | K39: 590.52 | L39: 37.91 | M39: 1028.87 | N39: 0 | O39: 813563.56 | P39: 24046614 | Q39: 29.6 | R39: 63.13 | S39: 5.88 | T39: 2024-04-03 | U39: 2024-07-01 | V39: 1318.84 | W39: 241.38 | X39: 347.23 | Y39: 246.68 | Z39: 207.06 | AA39: 245.5 | AB39: 195.9 | AC39: 82.69 | AD39: 489.92 | AE39: 58.12 | AF39: 68.05 | AG39: 31.57 | AH39: 40.545 | AI39: 22.81
... A60: FIN-0059 | B60: CUST-1175 | C60: 2022-Q1 | D60: WorkHub Pro | E60: Partner Referral | F60: Optimistic | G60: 15950.82 | H60: 191409.84 | I60: 579.47 | J60: 346330.69 | K60: 597.67 | L60: 9.62 | M60: 0 | N60: 0 | O60: 384769.33 | P60: 19367813 | Q60: 50.3 | R60: 57.91 | S60: 17.18 | T60: 2023-10-11 | U60: 2023-11-23 | V60: 3025.07 | W60: 7.48 | X60: 620.4 | Y60: 1229.18 | Z60: 719.15 | AA60: 748.56 | AB60: 484.23 | AC60: 1623.54 | AD60: 723.82 | AE60: 215.05 | AF60: 914.45 | AG60: 480.52 | AH60: 543.605 | AI60: 311.14
...

Sheet Descriptive Statistics
A1: Task 5 – Descriptive Statistics
A3: Metric | B3: N | C3: Mean | D3: Median | E3: Standard Deviation | F3: Skewness | G3: Kurtosis
A4: MRR_USD | B4: =COUNT('SaaS_Financials '!G:G) -> 1100 | C4: =AVERAGE('SaaS_Financials '!G:G) -> 9197.6271 | D4: =MEDIAN('SaaS_Financials '!G:G) -> 9282.295 | E4: =_xlfn.STDEV.S('SaaS_Financials '!G:G) -> 5197.143 | F4: =SKEW('SaaS_Financials '!G:G) -> -0.037256709 | G4: =KURT('SaaS_Financials '!G:G) -> -1.2034882
A5: LTV_CAC_Ratio | B5: =COUNTIF('SaaS_Financials '!K:K,">0") -> 994 | C5: =AVERAGEIF('SaaS_Financials '!K:K,">0") -> 638.76469 | D5: {=MEDIAN(IF('SaaS_Financials '!K:K>0,'SaaS_Financials '!K:K))} -> 341.79 | E5: {=_xlfn.STDEV.S(IF('SaaS_Financials '!K:K>0,'SaaS_Financials '!K:K))} -> 826.43507 | F5: {=SKEW(IF('SaaS_Financials '!K:K>0,'SaaS_Financials '!K:K))} -> 2.9007948 | G5: {=KURT(IF('SaaS_Financials '!K:K>0,'SaaS_Financials '!K:K))} -> 11.09666
A6: Resolution_Hours | B6: =COUNT(Support_Tickets!R:R) -> 4559 | C6: =AVERAGE(Support_Tickets!R:R) -> 56.617644 | D6: =MEDIAN(Support_Tickets!R:R) -> 30.83 | E6: =_xlfn.STDEV.S(Support_Tickets!R:R) -> 62.411665 | F6: =SKEW(Support_Tickets!R:R) -> 1.5605802 | G6: =KURT(Support_Tickets!R:R) -> 1.5353486
A7: Deal_Value_USD | B7: =COUNT(Sales_Pipeline!R:R) -> 4200 | C7: =AVERAGE(Sales_Pipeline!R:R) -> 37480.063 | D7: =MEDIAN(Sales_Pipeline!R:R) -> 13205 | E7: =_xlfn.STDEV.S(Sales_Pipeline!R:R) -> 52353.855 | F7: =SKEW(Sales_Pipeline!R:R) -> 1.9294989 | G7: =KURT(Sales_Pipeline!R:R) -> 2.6007192

Sheet Statistical Report
A1: Task 5 – Statistical Analysis Report
A2: Statistical validation of acquisition, sales, customer risk, activation, and churn
A4: 1. Hypothesis 1 – Win Rate Comparison
A5: Null Hypothesis (H₀): | B5: Product-Led Signup + Inbound Organic deals do not have a higher win rate than Cold Outreach + Paid Search deals.
A6: Alternative Hypothesis (H₁): | B6: Product-Led Signup + Inbound Organic deals have a higher win rate than Cold Outreach + Paid Search deals.
A7: Test: | B7: Two-Proportion Z-Test
A8: Confidence Level: | B8: 0.95
A9: Significance Level (α): | B9: 0.05
A10: Results:
A11: Product-Led + Inbound | B11: Won: 158 | Lost: 119 | Closed: 277 | Win Rate: 57.04%
A12: Cold + Paid | B12: Won: 163 | Lost: 152 | Closed: 315 | Win Rate: 51.75%
A13: Z-Statistic: | B13: 1.29
A14: One-Tailed p-value: | B14: 0.0985
A15: Decision: | B15: Fail to Reject H₀
A16: Business Interpretation: | B16: Product-Led Signup + Inbound Organic had a higher observed win rate (57.04% vs. 51.75%), but the difference was not statistically significant (p = 0.099 > 0.05). Therefore, there is not enough evidence to conclude that these channels have a higher win rate.
A18: 2. Hypothesis 2 – LTV/CAC by Acquisition Channel
A19: Null Hypothesis (H₀): | B19: Mean LTV/CAC ratio is the same across all acquisition channels.
A20: Alternative Hypothesis (H₁): | B20: At least one acquisition channel has a different mean LTV/CAC ratio.
A21: Test: | B21: One-Way ANOVA
A22: Confidence: | B22: 95% confidence; α = 0.05
A23: ANOVA F-Statistic: | B23: 108.1272
A24: ANOVA p-value: | B24: 1.03e-104
A25: Kruskal-Wallis: | B25: H = 334.8933; p = 2.70E-69
A26: Decision: | B26: Reject H₀
A27: Business Interpretation: | B27: LTV/CAC differs significantly across acquisition channels. ANOVA assumptions were violated because variances were unequal (Levene p < 0.001) and the data were strongly right-skewed, so Kruskal-Wallis is the primary result. Product-Led Signup showed the highest average LTV/CAC.
A29: 3. Hypothesis 3 – SLA Breach vs Churn Risk
A30: Null Hypothesis (H₀): | B30: SLA breach status in the first 90 days is independent of Churn Risk Flag.
A31: Alternative Hypothesis (H₁): | B31: Customers with one or more first-90-day SLA breaches have a different Churn Risk Flag.
A32: Test: | B32: Chi-Square Test of Independence
A33: Confidence: | B33: 95% confidence; α = 0.05
A34: Chi-Square Statistic: | B34: 0.034697
A35: Degrees of Freedom: | B35: 1
A36: p-value: | B36: 0.852232
A37: Decision: | B37: Fail to Reject H₀
A38: Business Interpretation: | B38: Customers with first-90-day SLA breaches did not show a statistically significant difference in Churn Risk Flag compared with customers without SLA breaches (χ² = 0.035, p = 0.852 > 0.05).
A40: 4. Hypothesis 4 – In-App Nudge vs Activation Rate
A41: Null Hypothesis (H₀): | B41: In-App Nudge campaigns do not have a higher average Activation Rate than non-In-App campaigns.
A42: Alternative Hypothesis (H₁): | B42: In-App Nudge campaigns have a higher average Activation Rate than non-In-App campaigns.
A43: Test: | B43: Independent Samples t-Test (Welch)
A44: Confidence: | B44: 95% confidence; α = 0.05
...

Sheet Churn Distribution
A1: Monthly_Churn_Rate_Pct | C1: Bin | D1: Frequency | H1: Churn Rate | I1: Lognormal Fitted Frequency | J1: Bin Center | K1: Lognormal Expected Frequency
A2: =SaaS_Financials__2[[#This Row],[Monthly_Churn_Rate_Pct]] -> 6.58 | C2: 5 | D2: =COUNTIFS($A$2:$A$1101,">"&C2-5,$A$2:$A$1101,"<="&C2) -> 421 | F2: =MIN(A2:A1101) -> 0.52 | H2: =MIN($A$2:$A$1101) -> 0.52 | J2: =5/2 -> 2.5 | K2: =COUNT($A$2:$A$1101)*_xlfn.LOGNORM.DIST(5,$I$57,$I$58,TRUE) -> 534.10118
A3: =SaaS_Financials__2[[#This Row],[Monthly_Churn_Rate_Pct]] -> 53.17 | C3: 10 | D3: =COUNTIFS($A$2:$A$1101,">"&C3-5,$A$2:$A$1101,"<="&C3) -> 483 | F3: =MAX(A2:A1101) -> 53.17 | H3: =H2+1 -> 1.52 | J3: =J2+5 -> 7.5 | K3: =COUNT($A$2:$A$1101)*(_xlfn.LOGNORM.DIST(J3+2.5,$I$57,$I$58,TRUE)-_xlfn.LOGNORM.DIST(J3-2.5,$I$57,$I$58,TRUE)) -> 346.73362
A4: =SaaS_Financials__2[[#This Row],[Monthly_Churn_Rate_Pct]] -> 6.06 | C4: 15 | D4: =COUNTIFS($A$2:$A$1101,">"&C4-5,$A$2:$A$1101,"<="&C4) -> 181 | H4: =H3+1 -> 2.52 | J4: =J3+5 -> 12.5 | K4: =COUNT($A$2:$A$1101)*(_xlfn.LOGNORM.DIST(J4+2.5,$I$57,$I$58,TRUE)-_xlfn.LOGNORM.DIST(J4-2.5,$I$57,$I$58,TRUE)) -> 123.46071
A5: =SaaS_Financials__2[[#This Row],[Monthly_Churn_Rate_Pct]] -> 2.94 | C5: 20 | D5: =COUNTIFS($A$2:$A$1101,">"&C5-5,$A$2:$A$1101,"<="&C5) -> 0 | H5: =H4+1 -> 3.52 | J5: =J4+5 -> 17.5 | K5: =COUNT($A$2:$A$1101)*(_xlfn.LOGNORM.DIST(J5+2.5,$I$57,$I$58,TRUE)-_xlfn.LOGNORM.DIST(J5-2.5,$I$57,$I$58,TRUE)) -> 49.205217
A6: =SaaS_Financials__2[[#This Row],[Monthly_Churn_Rate_Pct]] -> 1.56 | C6: 25 | D6: =COUNTIFS($A$2:$A$1101,">"&C6-5,$A$2:$A$1101,"<="&C6) -> 0 | H6: =H5+1 -> 4.52 | J6: =J5+5 -> 22.5 | K6: =COUNT($A$2:$A$1101)*(_xlfn.LOGNORM.DIST(J6+2.5,$I$57,$I$58,TRUE)-_xlfn.LOGNORM.DIST(J6-2.5,$I$57,$I$58,TRUE)) -> 21.968163
A7: =SaaS_Financials__2[[#This Row],[Monthly_Churn_Rate_Pct]] -> 7.78 | C7: 30 | D7: =COUNTIFS($A$2:$A$1101,">"&C7-5,$A$2:$A$1101,"<="&C7) -> 1 | H7: =H6+1 -> 5.52 | J7: =J6+5 -> 27.5 | K7: =COUNT($A$2:$A$1101)*(_xlfn.LOGNORM.DIST(J7+2.5,$I$57,$I$58,TRUE)-_xlfn.LOGNORM.DIST(J7-2.5,$I$57,$I$58,TRUE)) -> 10.731437
A8: =SaaS_Financials__2[[#This Row],[Monthly_Churn_Rate_Pct]] -> 2.22 | C8: 35 | D8: =COUNTIFS($A$2:$A$1101,">"&C8-5,$A$2:$A$1101,"<="&C8) -> 6 | H8: =H7+1 -> 6.52 | J8: =J7+5 -> 32.5 | K8: =COUNT($A$2:$A$1101)*(_xlfn.LOGNORM.DIST(J8+2.5,$I$57,$I$58,TRUE)-_xlfn.LOGNORM.DIST(J8-2.5,$I$57,$I$58,TRUE)) -> 5.6282269
A9: =SaaS_Financials__2[[#This Row],[Monthly_Churn_Rate_Pct]] -> 52.17 | C9: 40 | D9: =COUNTIFS($A$2:$A$1101,">"&C9-5,$A$2:$A$1101,"<="&C9) -> 1 | H9: =H8+1 -> 7.52 | J9: =J8+5 -> 37.5 | K9: =COUNT($A$2:$A$1101)*(_xlfn.LOGNORM.DIST(J9+2.5,$I$57,$I$58,TRUE)-_xlfn.LOGNORM.DIST(J9-2.5,$I$57,$I$58,TRUE)) -> 3.1254334
A10: =SaaS_Financials__2[[#This Row],[Monthly_Churn_Rate_Pct]] -> 9.74 | C10: 45 | D10: =COUNTIFS($A$2:$A$1101,">"&C10-5,$A$2:$A$1101,"<="&C10) -> 3 | H10: =H9+1 -> 8.52 | J10: =J9+5 -> 42.5 | K10: =COUNT($A$2:$A$1101)*(_xlfn.LOGNORM.DIST(J10+2.5,$I$57,$I$58,TRUE)-_xlfn.LOGNORM.DIST(J10-2.5,$I$57,$I$58,TRUE)) -> 1.8190394
A11: =SaaS_Financials__2[[#This Row],[Monthly_Churn_Rate_Pct]] -> 11.1 | C11: 50 | D11: =COUNTIFS($A$2:$A$1101,">"&C11-5,$A$2:$A$1101,"<="&C11) -> 1 | H11: =H10+1 -> 9.52 | J11: =J10+5 -> 47.5 | K11: =COUNT($A$2:$A$1101)*(_xlfn.LOGNORM.DIST(J11+2.5,$I$57,$I$58,TRUE)-_xlfn.LOGNORM.DIST(J11-2.5,$I$57,$I$58,TRUE)) -> 1.101126
A12: =SaaS_Financials__2[[#This Row],[Monthly_Churn_Rate_Pct]] -> 11.04 | C12: 55 | D12: =COUNTIFS($A$2:$A$1101,">"&C12-5,$A$2:$A$1101,"<="&C12) -> 3 | H12: =H11+1 -> 10.52 | J12: =J11+5 -> 52.5 | K12: =COUNT($A$2:$A$1101)*(_xlfn.LOGNORM.DIST(J12+2.5,$I$57,$I$58,TRUE)-_xlfn.LOGNORM.DIST(J12-2.5,$I$57,$I$58,TRUE)) -> 0.68918353
A13: =SaaS_Financials__2[[#This Row],[Monthly_Churn_Rate_Pct]] -> 8.31 | H13: =H12+1 -> 11.52
A14: =SaaS_Financials__2[[#This Row],[Monthly_Churn_Rate_Pct]] -> 11.14 | H14: =H13+1 -> 12.52
A15: =SaaS_Financials__2[[#This Row],[Monthly_Churn_Rate_Pct]] -> 8.57 | H15: =H14+1 -> 13.52
A16: =SaaS_Financials__2[[#This Row],[Monthly_Churn_Rate_Pct]] -> 11.71 | H16: =H15+1 -> 14.52
A17: =SaaS_Financials__2[[#This Row],[Monthly_Churn_Rate_Pct]] -> 3.93 | H17: =H16+1 -> 15.52
A18: =SaaS_Financials__2[[#This Row],[Monthly_Churn_Rate_Pct]] -> 5.41 | H18: =H17+1 -> 16.52
A19: =SaaS_Financials__2[[#This Row],[Monthly_Churn_Rate_Pct]] -> 32.88 | H19: =H18+1 -> 17.52
A20: =SaaS_Financials__2[[#This Row],[Monthly_Churn_Rate_Pct]] -> 3.37 | H20: =H19+1 -> 18.52
A21: =SaaS_Financials__2[[#This Row],[Monthly_Churn_Rate_Pct]] -> 9.28 | H21: =H20+1 -> 19.52
A22: =SaaS_Financials__2[[#This Row],[Monthly_Churn_Rate_Pct]] -> 3.77 | H22: =H21+1 -> 20.52
A23: =SaaS_Financials__2[[#This Row],[Monthly_Churn_Rate_Pct]] -> 5.76 | H23: =H22+1 -> 21.52
A24: =SaaS_Financials__2[[#This Row],[Monthly_Churn_Rate_Pct]] -> 1.82 | H24: =H23+1 -> 22.52
... A55: =SaaS_Financials__2[[#This Row],[Monthly_Churn_Rate_Pct]] -> 9.05 | H55: =H54+1 -> 53.52
A56: =SaaS_Financials__2[[#This Row],[Monthly_Churn_Rate_Pct]] -> 1.31
A57: =SaaS_Financials__2[[#This Row],[Monthly_Churn_Rate_Pct]] -> 10.15 | H57: Lognormal Mu | I57: {=AVERAGE(LN($A$2:$A$1101))} -> 1.6379624
A58: =SaaS_Financials__2[[#This Row],[Monthly_Churn_Rate_Pct]] -> 8.12 | H58: Lognormal Sigma | I58: {=_xlfn.STDEV.P(LN($A$2:$A$1101))} -> 0.78715514
A59: =SaaS_Financials__2[[#This Row],[Monthly_Churn_Rate_Pct]] -> 7.99
A60: =SaaS_Financials__2[[#This Row],[Monthly_Churn_Rate_Pct]] -> 9.62
A61: =SaaS_Financials__2[[#This Row],[Monthly_Churn_Rate_Pct]] -> 9.33
A62: =SaaS_Financials__2[[#This Row],[Monthly_Churn_Rate_Pct]] -> 3.46
A63: =SaaS_Financials__2[[#This Row],[Monthly_Churn_Rate_Pct]] -> 2.15
A64: =SaaS_Financials__2[[#This Row],[Monthly_Churn_Rate_Pct]] -> 3.91
A65: =SaaS_Financials__2[[#This Row],[Monthly_Churn_Rate_Pct]] -> 10.55
A66: =SaaS_Financials__2[[#This Row],[Monthly_Churn_Rate_Pct]] -> 2.5
A67: =SaaS_Financials__2[[#This Row],[Monthly_Churn_Rate_Pct]] -> 11.12
A68: =SaaS_Financials__2[[#This Row],[Monthly_Churn_Rate_Pct]] -> 9.92
A69: =SaaS_Financials__2[[#This Row],[Monthly_Churn_Rate_Pct]] -> 7.15
A70: =SaaS_Financials__2[[#This Row],[Monthly_Churn_Rate_Pct]] -> 0.56
...

Sheet Correlation
A1: NPS_Score | B1: Monthly_Churn_Rate_Pct | D1: Pearson Correlation
A2: ='Customers'!J2 -> 8 | B2: =IFERROR(AVERAGEIF('SaaS_Financials '!$B$2:$B$1101,'Customers'!A2,'SaaS_Financials '!$L$2:$L$1101),"") -> 7.545 | D2: {=CORREL(_xlfn._xlws.FILTER(A2:A1521,B2:B1521<>""),_xlfn._xlws.FILTER(B2:B1521,B2:B1521<>""))} -> -0.002168514
A3: ='Customers'!J3 -> 9 | B3: =IFERROR(AVERAGEIF('SaaS_Financials '!$B$2:$B$1101,'Customers'!A3,'SaaS_Financials '!$L$2:$L$1101),"") | D3: Interpretation
A4: ='Customers'!J4 -> 15 | B4: =IFERROR(AVERAGEIF('SaaS_Financials '!$B$2:$B$1101,'Customers'!A4,'SaaS_Financials '!$L$2:$L$1101),"") -> 4.28 | D4: Virtually no linear relationship between NPS Score and Monthly Churn Rate (r = -0.00217).
A5: ='Customers'!J5 -> 91 | B5: =IFERROR(AVERAGEIF('SaaS_Financials '!$B$2:$B$1101,'Customers'!A5,'SaaS_Financials '!$L$2:$L$1101),"") -> 3.495
A6: ='Customers'!J6 -> 0 | B6: =IFERROR(AVERAGEIF('SaaS_Financials '!$B$2:$B$1101,'Customers'!A6,'SaaS_Financials '!$L$2:$L$1101),"")
A7: ='Customers'!J7 -> 59 | B7: =IFERROR(AVERAGEIF('SaaS_Financials '!$B$2:$B$1101,'Customers'!A7,'SaaS_Financials '!$L$2:$L$1101),"")
A8: ='Customers'!J8 -> 40 | B8: =IFERROR(AVERAGEIF('SaaS_Financials '!$B$2:$B$1101,'Customers'!A8,'SaaS_Financials '!$L$2:$L$1101),"") -> 10.42
A9: ='Customers'!J9 -> 7 | B9: =IFERROR(AVERAGEIF('SaaS_Financials '!$B$2:$B$1101,'Customers'!A9,'SaaS_Financials '!$L$2:$L$1101),"")
A10: ='Customers'!J10 -> 70 | B10: =IFERROR(AVERAGEIF('SaaS_Financials '!$B$2:$B$1101,'Customers'!A10,'SaaS_Financials '!$L$2:$L$1101),"") -> 4.64
A11: ='Customers'!J11 -> 0 | B11: =IFERROR(AVERAGEIF('SaaS_Financials '!$B$2:$B$1101,'Customers'!A11,'SaaS_Financials '!$L$2:$L$1101),"")
A12: ='Customers'!J12 -> 80 | B12: =IFERROR(AVERAGEIF('SaaS_Financials '!$B$2:$B$1101,'Customers'!A12,'SaaS_Financials '!$L$2:$L$1101),"") -> 7.9
A13: ='Customers'!J13 -> 59 | B13: =IFERROR(AVERAGEIF('SaaS_Financials '!$B$2:$B$1101,'Customers'!A13,'SaaS_Financials '!$L$2:$L$1101),"") -> 9.96
A14: ='Customers'!J14 -> 0 | B14: =IFERROR(AVERAGEIF('SaaS_Financials '!$B$2:$B$1101,'Customers'!A14,'SaaS_Financials '!$L$2:$L$1101),"") -> 2.73
A15: ='Customers'!J15 -> 41 | B15: =IFERROR(AVERAGEIF('SaaS_Financials '!$B$2:$B$1101,'Customers'!A15,'SaaS_Financials '!$L$2:$L$1101),"") -> 6.87
A16: ='Customers'!J16 -> 64 | B16: =IFERROR(AVERAGEIF('SaaS_Financials '!$B$2:$B$1101,'Customers'!A16,'SaaS_Financials '!$L$2:$L$1101),"")
... A1521: ='Customers'!J1521 -> 46 | B1521: =IFERROR(AVERAGEIF('SaaS_Financials '!$B$2:$B$1101,'Customers'!A1521,'SaaS_Financials '!$L$2:$L$1101),"") -> 7.1625

Sheet Summary
A1: Task 5 – Statistical Validation Summary
A2: Statistical testing of business performance, customer risk, acquisition, and churn
A4: Hypothesis | B4: Test | C4: Statistic | D4: p-value | E4: Decision | F4: Business Interpretation
A5: H1 – Win Rate | B5: Two-Proportion Z-Test | C5: 1.28996 | D5: 0.09853 | E5: Fail to Reject H0 | F5: Product-Led Signup + Inbound Organic had a higher observed win rate, but the difference was not statistically significant.
A6: H2 – LTV/CAC | B6: One-Way ANOVA + Kruskal-Wallis | C6: 334.8933 | D6: 2.696e-69 | E6: Reject H0 | F6: LTV/CAC differs significantly across acquisition channels. ANOVA assumptions were violated, so Kruskal-Wallis is the primary result.
A7: H3 – SLA Breach | B7: Chi-Square Test | C7: 0.034697 | D7: 0.852232 | E7: Fail to Reject H0 | F7: Customers with first-90-day SLA breaches did not show a statistically significant difference in Churn Risk Flag.
A8: H4 – In-App Nudge | B8: Independent Samples t-Test | C8: 4.68802 | D8: 1.07E-05 | E8: Reject H0 | F8: In-App Nudge campaigns had a significantly higher Activation Rate than non-In-App campaigns.
A11: Metric | B11: N | C11: Mean | D11: Median | E11: Standard Deviation | F11: Skewness | G11: Kurtosis
A12: MRR_USD | B12: =COUNT('SaaS_Financials '!G:G) -> 1100 | C12: =AVERAGE('SaaS_Financials '!G:G) -> 9197.6271 | D12: =MEDIAN('SaaS_Financials '!G:G) -> 9282.295 | E12: =_xlfn.STDEV.S('SaaS_Financials '!G:G) -> 5197.143 | F12: =SKEW('SaaS_Financials '!G:G) -> -0.037256709 | G12: =KURT('SaaS_Financials '!G:G) -> -1.2034882
A13: LTV_CAC_Ratio | B13: =COUNTIF('SaaS_Financials '!K:K,">0") -> 994 | C13: =AVERAGEIF('SaaS_Financials '!K:K,">0") -> 638.76469 | D13: {=MEDIAN(IF('SaaS_Financials '!K:K>0,'SaaS_Financials '!K:K))} -> 341.79 | E13: {=_xlfn.STDEV.S(IF('SaaS_Financials '!K:K>0,'SaaS_Financials '!K:K))} -> 826.43507 | F13: {=SKEW(IF('SaaS_Financials '!K:K>0,'SaaS_Financials '!K:K))} -> 2.9007948 | G13: {=KURT(IF('SaaS_Financials '!K:K>0,'SaaS_Financials '!K:K))} -> 11.09666
A14: Resolution_Hours | B14: =COUNTIF(Support_Tickets!I:I,">=0") -> 4663 | C14: =AVERAGEIF(Support_Tickets!I:I,">=0") -> 56.473086 | D14: {=MEDIAN(_xlfn._xlws.FILTER(Support_Tickets!I:I,Support_Tickets!I:I>=0))} -> 30.42 | E14: {=_xlfn.STDEV.S(_xlfn._xlws.FILTER(Support_Tickets!I:I,Support_Tickets!I:I>=0))} -> 62.513116 | F14: {=SKEW(_xlfn._xlws.FILTER(Support_Tickets!I:I,Support_Tickets!I:I>=0))} -> 1.5685388 | G14: {=KURT(_xlfn._xlws.FILTER(Support_Tickets!I:I,Support_Tickets!I:I>=0))} -> 1.5571277
A15: Deal_Value_USD | B15: =COUNT(Sales_Pipeline!R:R) -> 4200 | C15: =AVERAGE(Sales_Pipeline!R:R) -> 37480.063 | D15: =MEDIAN(Sales_Pipeline!R:R) -> 13205 | E15: =_xlfn.STDEV.S(Sales_Pipeline!R:R) -> 52353.855 | F15: =SKEW(Sales_Pipeline!R:R) -> 1.9294989 | G15: =KURT(Sales_Pipeline!R:R) -> 2.6007192
A18: Analysis | B18: Result
A19: Best-Fit Churn Distribution | B19: Lognormal
A20: Lognormal Mu | B20: 1.6379624
A21: Lognormal Sigma | B21: 0.78715514
A22: Churn Rate Range | B22: 0.52% – 53.17%
A23: Pearson Correlation | B23: -0.00217
A24: Correlation Interpretation | B24: Virtually no linear relationship between NPS Score and Monthly Churn Rate.
A27: Overall Conclusion | B27: The analysis shows that acquisition channel significantly affects LTV/CAC and In-App Nudge campaigns significantly improve activation. However, the win-rate difference and SLA-breach relationship with churn risk were not statistically significant. Monthly churn is strongly right-skewed, with a Lognormal distribution providing the best fit, while NPS has virtually no linear relationship with churn.

Sheet Support_Tickets
A1: Ticket_ID | B1: Customer_ID | C1: Deal_ID | D1: Category | E1: Priority | F1: Status | G1: Created_Date | H1: Resolved_Date | I1: Resolution_Hours | J1: SLA_Target_Hours | K1: SLA_Met | L1: Assigned_Agent | M1: Contact_Channel | N1: CSAT_Score | O1: Automation_Flag | P1: Created_Date_Clean | Q1: Unique_Ticket | R1: Resolution_Hours_Clean
A2: TKT-00001 | B2: CUST-0751 | C2: DL-02878 | D2: Integration Issue | E2: Medium | F2: Resolved | G2: 2024-11-01 | J2: 24 | L2: Chatura Bal | M2: Slack Integration | O2: False | P2: =IFERROR(DATEVALUE(G2),IFERROR(DATE(RIGHT(G2,4),MID(G2,4,2),LEFT(G2,2)),"")) -> 45597 | Q2: =--(COUNTIF($A$2:A2,A2)=1) -> 1 | R2: =IF(AND(Q2=1,I2<>"",ISNUMBER(I2),I2>=0),I2,"")
A3: TKT-00002 | B3: CUST-0976 | C3: DL-01196 | D3: Access & Permissions | E3: High | F3: Resolved | G3: 2023-01-24 | H3: 44950 | I3: 22.76 | J3: 8 | K3: No | L3: Nidhi Bora | M3: Help Portal | O3: True | P3: =IFERROR(DATEVALUE(G3),IFERROR(DATE(RIGHT(G3,4),MID(G3,4,2),LEFT(G3,2)),"")) -> 44950 | Q3: =--(COUNTIF($A$2:A3,A3)=1) -> 1 | R3: =IF(AND(Q3=1,I3<>"",ISNUMBER(I3),I3>=0),I3,"") -> 22.76
A4: TKT-00003 | B4: CUST-0599 | D4: Integration Issue | E4: Medium | F4: In Progress | G4: 2023-09-10 | J4: 24 | L4: Fiyaz Chawla | M4: Slack Integration | O4: 0 | P4: =IFERROR(DATEVALUE(G4),IFERROR(DATE(RIGHT(G4,4),MID(G4,4,2),LEFT(G4,2)),"")) -> 45179 | Q4: =--(COUNTIF($A$2:A4,A4)=1) -> 1 | R4: =IF(AND(Q4=1,I4<>"",ISNUMBER(I4),I4>=0),I4,"") | U4: N | V4: =COUNT(R:R) -> 4559
A5: TKT-00004 | B5: CUST-0454 | C5: DL-00550 | D5: Performance Issue | E5: Medium | F5: Resolved | G5: 2025-02-18 | J5: 24 | L5: Abha Dugal | M5: In-App Chat | O5: FALSE | P5: =IFERROR(DATEVALUE(G5),IFERROR(DATE(RIGHT(G5,4),MID(G5,4,2),LEFT(G5,2)),"")) -> 45706 | Q5: =--(COUNTIF($A$2:A5,A5)=1) -> 1 | R5: =IF(AND(Q5=1,I5<>"",ISNUMBER(I5),I5>=0),I5,"")
A6: TKT-00005 | B6: CUST-0090 | D6: Integration Issue | E6: High | F6: Resolved | G6: 20/07/2023 | H6: 45127 | I6: 21.49 | J6: 8 | K6: No | L6: Dayita Palan | M6: In-App Chat | N6: 2.3 | O6: FALSE | P6: =IFERROR(DATEVALUE(G6),IFERROR(DATE(RIGHT(G6,4),MID(G6,4,2),LEFT(G6,2)),"")) -> 45127 | Q6: =--(COUNTIF($A$2:A6,A6)=1) -> 1 | R6: =IF(AND(Q6=1,I6<>"",ISNUMBER(I6),I6>=0),I6,"") -> 21.49 | U6: Mean: | V6: =AVERAGE(R:R) -> 56.617644
A7: TKT-00006 | B7: CUST-1099 | D7: Access & Permissions | E7: Low | F7: Resolved | G7: 2022-04-07 | H7: 44660 | I7: 58.66 | J7: 72 | K7: Yes | L7: Abha Dugal | M7: Help Portal | N7: 2.6 | O7: No | P7: =IFERROR(DATEVALUE(G7),IFERROR(DATE(RIGHT(G7,4),MID(G7,4,2),LEFT(G7,2)),"")) -> 44658 | Q7: =--(COUNTIF($A$2:A7,A7)=1) -> 1 | R7: =IF(AND(Q7=1,I7<>"",ISNUMBER(I7),I7>=0),I7,"") -> 58.66 | T7: =COUNT(R:R) -> 4559
A8: TKT-00007 | B8: CUST-1099 | D8: Data Discrepancy | E8: Medium | F8: Resolved | G8: 2024-12-23 | H8: 45651 | I8: 65.52 | J8: 24 | K8: No | L8: Darika Pau | M8: In-App Chat | O8: Yes | P8: =IFERROR(DATEVALUE(G8),IFERROR(DATE(RIGHT(G8,4),MID(G8,4,2),LEFT(G8,2)),"")) -> 45649 | Q8: =--(COUNTIF($A$2:A8,A8)=1) -> 1 | R8: =IF(AND(Q8=1,I8<>"",ISNUMBER(I8),I8>=0),I8,"") -> 65.52 | U8: Median | V8: =MEDIAN(R:R) -> 30.83
A9: TKT-00008 | B9: CUST-1302 | D9: Feature Request | E9: Low | F9: Resolved | G9: 2024-09-27 | H9: 45567 | I9: 131.51 | J9: 72 | K9: No | L9: Bhavini Sheth | M9: Phone | O9: FALSE | P9: =IFERROR(DATEVALUE(G9),IFERROR(DATE(RIGHT(G9,4),MID(G9,4,2),LEFT(G9,2)),"")) -> 45562 | Q9: =--(COUNTIF($A$2:A9,A9)=1) -> 1 | R9: =IF(AND(Q9=1,I9<>"",ISNUMBER(I9),I9>=0),I9,"") -> 131.51 | T9: =COUNTIF(R:R,">=0") -> 4559
A10: TKT-00009 | B10: CUST-1269 | C10: DL-01325 | D10: Performance Issue | E10: Low | F10: Resolved | G10: 2022-06-03 | H10: 44718 | I10: 78.59 | J10: 72 | K10: No | L10: Peter Shan | M10: Email | N10: 1.4 | O10: FALSE | P10: =IFERROR(DATEVALUE(G10),IFERROR(DATE(RIGHT(G10,4),MID(G10,4,2),LEFT(G10,2)),"")) -> 44715 | Q10: =--(COUNTIF($A$2:A10,A10)=1) -> 1 | R10: =IF(AND(Q10=1,I10<>"",ISNUMBER(I10),I10>=0),I10,"") -> 78.59 | U10: Standard deviation: | V10: =_xlfn.STDEV.S(R:R) -> 62.411665
A11: TKT-00010 | B11: CUST-0478 | D11: Performance Issue | E11: Low | F11: Resolved | G11: 2024-09-03 | H11: 45541 | I11: 89.4 | J11: 72 | K11: No | L11: Bhanumati Savant | M11: Help Portal | N11: 1 | O11: True | P11: =IFERROR(DATEVALUE(G11),IFERROR(DATE(RIGHT(G11,4),MID(G11,4,2),LEFT(G11,2)),"")) -> 45538 | Q11: =--(COUNTIF($A$2:A11,A11)=1) -> 1 | R11: =IF(AND(Q11=1,I11<>"",ISNUMBER(I11),I11>=0),I11,"") -> 89.4 | T11: =COUNTIF(R:R,0) -> 0
A12: TKT-00011 | B12: CUST-1453 | D12: Performance Issue | E12: High | F12: Resolved | G12: 2023-12-04 | H12: 45264 | I12: 5.45 | J12: 8 | K12: Yes | L12: Ayush Banerjee | M12: Slack Integration | N12: 2.7 | O12: TRUE | P12: =IFERROR(DATEVALUE(G12),IFERROR(DATE(RIGHT(G12,4),MID(G12,4,2),LEFT(G12,2)),"")) -> 45264 | Q12: =--(COUNTIF($A$2:A12,A12)=1) -> 1 | R12: =IF(AND(Q12=1,I12<>"",ISNUMBER(I12),I12>=0),I12,"") -> 5.45 | U12: skewness: | V12: =SKEW(R:R) -> 1.5605802
A13: TKT-00012 | B13: CUST-0023 | C13: DL-02589 | D13: Data Discrepancy | E13: Low | F13: Resolved | G13: 2024-07-23 | H13: 45502 | I13: 157.18 | J13: 72 | K13: No | L13: Arin Dass | M13: Phone | N13: 3.6 | O13: TRUE | P13: =IFERROR(DATEVALUE(G13),IFERROR(DATE(RIGHT(G13,4),MID(G13,4,2),LEFT(G13,2)),"")) -> 45496 | Q13: =--(COUNTIF($A$2:A13,A13)=1) -> 1 | R13: =IF(AND(Q13=1,I13<>"",ISNUMBER(I13),I13>=0),I13,"") -> 157.18
A14: TKT-00013 | B14: CUST-0831 | D14: Data Discrepancy | E14: High | F14: Resolved | G14: 2022-12-07 | J14: 8 | L14: Neel Oza | M14: Help Portal | O14: TRUE | P14: =IFERROR(DATEVALUE(G14),IFERROR(DATE(RIGHT(G14,4),MID(G14,4,2),LEFT(G14,2)),"")) -> 44902 | Q14: =--(COUNTIF($A$2:A14,A14)=1) -> 1 | R14: =IF(AND(Q14=1,I14<>"",ISNUMBER(I14),I14>=0),I14,"") | U14: kurtosis: | V14: =KURT(R:R) -> 1.5353486
A15: TKT-00014 | B15: CUST-0874 | D15: Data Discrepancy | E15: Low | F15: Escalated | G15: 2024-02-20 | H15: 45347 | I15: 143.5 | J15: 72 | K15: No | L15: Hemangini Mangat | M15: Phone | N15: 2.4 | O15: True | P15: =IFERROR(DATEVALUE(G15),IFERROR(DATE(RIGHT(G15,4),MID(G15,4,2),LEFT(G15,2)),"")) -> 45342 | Q15: =--(COUNTIF($A$2:A15,A15)=1) -> 1 | R15: =IF(AND(Q15=1,I15<>"",ISNUMBER(I15),I15>=0),I15,"") -> 143.5
A16: TKT-00015 | B16: CUST-0989 | C16: DL-01854 | D16: Access & Permissions | E16: Low | F16: Resolved | G16: 2025-02-22 | H16: 45717 | I16: 175.8 | J16: 72 | K16: No | L16: Odika Ganesh | M16: In-App Chat | N16: 3.1 | O16: False | P16: =IFERROR(DATEVALUE(G16),IFERROR(DATE(RIGHT(G16,4),MID(G16,4,2),LEFT(G16,2)),"")) -> 45710 | Q16: =--(COUNTIF($A$2:A16,A16)=1) -> 1 | R16: =IF(AND(Q16=1,I16<>"",ISNUMBER(I16),I16>=0),I16,"") -> 175.8
A17: TKT-00016 | B17: CUST-1289 | D17: Account Management | E17: High | F17: Open | G17: 2023-04-14 | J17: 8 | L17: Dipta Nadig | M17: Phone | O17: No | P17: =IFERROR(DATEVALUE(G17),IFERROR(DATE(RIGHT(G17,4),MID(G17,4,2),LEFT(G17,2)),"")) -> 45030 | Q17: =--(COUNTIF($A$2:A17,A17)=1) -> 1 | R17: =IF(AND(Q17=1,I17<>"",ISNUMBER(I17),I17>=0),I17,"")
A18: TKT-00017 | B18: CUST-1317 | D18: Account Management | E18: High | F18: Resolved | G18: 2024-06-25 | H18: 45468 | I18: 16.34 | J18: 8 | K18: No | L18: Anita Saxena | M18: In-App Chat | N18: 4.7 | O18: No | P18: =IFERROR(DATEVALUE(G18),IFERROR(DATE(RIGHT(G18,4),MID(G18,4,2),LEFT(G18,2)),"")) -> 45468 | Q18: =--(COUNTIF($A$2:A18,A18)=1) -> 1 | R18: =IF(AND(Q18=1,I18<>"",ISNUMBER(I18),I18>=0),I18,"") -> 16.34
A19: TKT-00018 | B19: CUST-0105 | C19: DL-03503 | D19: Data Discrepancy | E19: Medium | F19: Open | G19: 2024-10-22 | J19: 24 | L19: Neel Oza | M19: Help Portal | O19: No | P19: =IFERROR(DATEVALUE(G19),IFERROR(DATE(RIGHT(G19,4),MID(G19,4,2),LEFT(G19,2)),"")) -> 45587 | Q19: =--(COUNTIF($A$2:A19,A19)=1) -> 1 | R19: =IF(AND(Q19=1,I19<>"",ISNUMBER(I19),I19>=0),I19,"")
A20: TKT-00019 | B20: CUST-0131 | C20: DL-01941 | D20: Billing & Payments | E20: Medium | F20: Resolved | G20: 2022-10-22 | H20: 44859 | I20: 74.88 | J20: 24 | K20: No | L20: Chatura Bal | M20: Slack Integration | O20: Yes | P20: =IFERROR(DATEVALUE(G20),IFERROR(DATE(RIGHT(G20,4),MID(G20,4,2),LEFT(G20,2)),"")) -> 44856 | Q20: =--(COUNTIF($A$2:A20,A20)=1) -> 1 | R20: =IF(AND(Q20=1,I20<>"",ISNUMBER(I20),I20>=0),I20,"") -> 74.88
A21: TKT-00020 | B21: CUST-1372 | D21: Technical Bug | E21: Low | F21: Open | G21: 2023-09-25 | J21: 72 | L21: Dipta Nadig | M21: Slack Integration | O21: TRUE | P21: =IFERROR(DATEVALUE(G21),IFERROR(DATE(RIGHT(G21,4),MID(G21,4,2),LEFT(G21,2)),"")) -> 45194 | Q21: =--(COUNTIF($A$2:A21,A21)=1) -> 1 | R21: =IF(AND(Q21=1,I21<>"",ISNUMBER(I21),I21>=0),I21,"")
A22: TKT-00021 | B22: CUST-1487 | C22: DL-00949 | D22: Performance Issue | E22: Low | F22: Escalated | G22: 2024-06-07 | H22: 45455 | I22: 131.61 | J22: 72 | K22: No | L22: Eshana Soni | M22: Email | O22: False | P22: =IFERROR(DATEVALUE(G22),IFERROR(DATE(RIGHT(G22,4),MID(G22,4,2),LEFT(G22,2)),"")) -> 45450 | Q22: =--(COUNTIF($A$2:A22,A22)=1) -> 1 | R22: =IF(AND(Q22=1,I22<>"",ISNUMBER(I22),I22>=0),I22,"") -> 131.61
A23: TKT-00022 | B23: CUST-0619 | C23: DL-03703 | D23: Data Discrepancy | E23: Low | F23: Resolved | G23: 2024-11-11 | H23: 45615 | I23: 198.8 | J23: 72 | K23: No | L23: Utkarsh Chakraborty | M23: Slack Integration | N23: 3.1 | O23: True | P23: =IFERROR(DATEVALUE(G23),IFERROR(DATE(RIGHT(G23,4),MID(G23,4,2),LEFT(G23,2)),"")) -> 45607 | Q23: =--(COUNTIF($A$2:A23,A23)=1) -> 1 | R23: =IF(AND(Q23=1,I23<>"",ISNUMBER(I23),I23>=0),I23,"") -> 198.8
A24: TKT-00023 | B24: CUST-0095 | D24: Onboarding Support | E24: Low | F24: Resolved | G24: 2023-05-27 | H24: 45075 | I24: 53.66 | J24: 72 | K24: Yes | L24: Arin Dass | M24: In-App Chat | N24: 2.5 | O24: TRUE | P24: =IFERROR(DATEVALUE(G24),IFERROR(DATE(RIGHT(G24,4),MID(G24,4,2),LEFT(G24,2)),"")) -> 45073 | Q24: =--(COUNTIF($A$2:A24,A24)=1) -> 1 | R24: =IF(AND(Q24=1,I24<>"",ISNUMBER(I24),I24>=0),I24,"") -> 53.66
A25: TKT-00024 | B25: CUST-0374 | D25: Onboarding Support | E25: Medium | F25: Resolved | G25: 2022-01-15 | H25: 44578 | I25: 50.89 | J25: 24 | K25: No | L25: Dayamai Karnik | M25: Help Portal | N25: 2.7 | O25: True | P25: =IFERROR(DATEVALUE(G25),IFERROR(DATE(RIGHT(G25,4),MID(G25,4,2),LEFT(G25,2)),"")) -> 44576 | Q25: =--(COUNTIF($A$2:A25,A25)=1) -> 1 | R25: =IF(AND(Q25=1,I25<>"",ISNUMBER(I25),I25>=0),I25,"") -> 50.89
A26: TKT-00025 | B26: CUST-0097 | D26: Account Management | E26: High | F26: Resolved | G26: 2022-06-29 | H26: 44741 | I26: 5.3 | J26: 8 | K26: Yes | M26: Phone | O26: Yes | P26: =IFERROR(DATEVALUE(G26),IFERROR(DATE(RIGHT(G26,4),MID(G26,4,2),LEFT(G26,2)),"")) -> 44741 | Q26: =--(COUNTIF($A$2:A26,A26)=1) -> 1 | R26: =IF(AND(Q26=1,I26<>"",ISNUMBER(I26),I26>=0),I26,"") -> 5.3
A27: TKT-00026 | B27: CUST-0487 | D27: Account Management | E27: Medium | F27: Resolved | G27: 2023-07-02 | J27: 24 | L27: Dayamai Karnik | M27: Slack Integration | O27: 0 | P27: =IFERROR(DATEVALUE(G27),IFERROR(DATE(RIGHT(G27,4),MID(G27,4,2),LEFT(G27,2)),"")) -> 45109 | Q27: =--(COUNTIF($A$2:A27,A27)=1) -> 1 | R27: =IF(AND(Q27=1,I27<>"",ISNUMBER(I27),I27>=0),I27,"")
A28: TKT-00027 | B28: CUST-0965 | C28: DL-03232 | D28: Performance Issue | E28: Medium | F28: Resolved | G28: 2023-12-29 | H28: 45289 | I28: 9.97 | J28: 24 | K28: Yes | L28: Odika Ganesh | M28: Help Portal | N28: 1.8 | O28: 1 | P28: =IFERROR(DATEVALUE(G28),IFERROR(DATE(RIGHT(G28,4),MID(G28,4,2),LEFT(G28,2)),"")) -> 45289 | Q28: =--(COUNTIF($A$2:A28,A28)=1) -> 1 | R28: =IF(AND(Q28=1,I28<>"",ISNUMBER(I28),I28>=0),I28,"") -> 9.97
A29: TKT-00028 | B29: CUST-0178 | C29: DL-01013 | D29: Account Management | E29: High | F29: In Progress | G29: 2023-03-21 | J29: 8 | L29: Arin Dass | M29: Phone | O29: FALSE | P29: =IFERROR(DATEVALUE(G29),IFERROR(DATE(RIGHT(G29,4),MID(G29,4,2),LEFT(G29,2)),"")) -> 45006 | Q29: =--(COUNTIF($A$2:A29,A29)=1) -> 1 | R29: =IF(AND(Q29=1,I29<>"",ISNUMBER(I29),I29>=0),I29,"")
A30: TKT-00029 | B30: CUST-0880 | D30: Integration Issue | E30: Medium | F30: In Progress | G30: 22/11/2022 | J30: 24 | L30: Sai Patil | M30: In-App Chat | O30: False | P30: =IFERROR(DATEVALUE(G30),IFERROR(DATE(RIGHT(G30,4),MID(G30,4,2),LEFT(G30,2)),"")) -> 44887 | Q30: =--(COUNTIF($A$2:A30,A30)=1) -> 1 | R30: =IF(AND(Q30=1,I30<>"",ISNUMBER(I30),I30>=0),I30,"")
A31: TKT-00030 | B31: CUST-1082 | C31: DL-03821 | D31: Access & Permissions | E31: High | F31: Resolved | G31: 2022-10-18 | H31: 44853 | I31: 27.38 | J31: 8 | K31: No | L31: Ojas Ranganathan | M31: Phone | N31: 1.1 | O31: TRUE | P31: =IFERROR(DATEVALUE(G31),IFERROR(DATE(RIGHT(G31,4),MID(G31,4,2),LEFT(G31,2)),"")) -> 44852 | Q31: =--(COUNTIF($A$2:A31,A31)=1) -> 1 | R31: =IF(AND(Q31=1,I31<>"",ISNUMBER(I31),I31>=0),I31,"") -> 27.38
A32: TKT-00031 | B32: CUST-0736 | D32: Technical Bug | E32: Medium | F32: Open | G32: 2023-07-15 | J32: 24 | L32: Sanya Brar | M32: Phone | O32: TRUE | P32: =IFERROR(DATEVALUE(G32),IFERROR(DATE(RIGHT(G32,4),MID(G32,4,2),LEFT(G32,2)),"")) -> 45122 | Q32: =--(COUNTIF($A$2:A32,A32)=1) -> 1 | R32: =IF(AND(Q32=1,I32<>"",ISNUMBER(I32),I32>=0),I32,"")
A33: TKT-00032 | B33: CUST-0715 | D33: Account Management | E33: Medium | F33: Resolved | G33: 2024-05-01 | H33: 45414 | I33: 38.42 | J33: 24 | K33: No | L33: Fiyaz Chawla | M33: Phone | N33: 3.5 | O33: False | P33: =IFERROR(DATEVALUE(G33),IFERROR(DATE(RIGHT(G33,4),MID(G33,4,2),LEFT(G33,2)),"")) -> 45413 | Q33: =--(COUNTIF($A$2:A33,A33)=1) -> 1 | R33: =IF(AND(Q33=1,I33<>"",ISNUMBER(I33),I33>=0),I33,"") -> 38.42
A34: TKT-00033 | B34: CUST-0148 | D34: Onboarding Support | E34: Low | F34: Resolved | G34: 2022-06-04 | H34: 44724 | I34: 215.2 | J34: 72 | K34: No | L34: Dayamai Karnik | M34: Help Portal | O34: TRUE | P34: =IFERROR(DATEVALUE(G34),IFERROR(DATE(RIGHT(G34,4),MID(G34,4,2),LEFT(G34,2)),"")) -> 44716 | Q34: =--(COUNTIF($A$2:A34,A34)=1) -> 1 | R34: =IF(AND(Q34=1,I34<>"",ISNUMBER(I34),I34>=0),I34,"") -> 215.2
A35: TKT-00034 | B35: CUST-0274 | D35: Access & Permissions | E35: Medium | F35: In Progress | G35: 2024-02-09 | J35: 24 | L35: Odika Ganesh | M35: In-App Chat | O35: 0 | P35: =IFERROR(DATEVALUE(G35),IFERROR(DATE(RIGHT(G35,4),MID(G35,4,2),LEFT(G35,2)),"")) -> 45331 | Q35: =--(COUNTIF($A$2:A35,A35)=1) -> 1 | R35: =IF(AND(Q35=1,I35<>"",ISNUMBER(I35),I35>=0),I35,"")
A36: TKT-00035 | B36: CUST-0276 | D36: Integration Issue | E36: Low | F36: Resolved | G36: 2025-01-29 | H36: 45693 | I36: 171.42 | J36: 72 | K36: No | L36: Chatura Bal | M36: Email | O36: True | P36: =IFERROR(DATEVALUE(G36),IFERROR(DATE(RIGHT(G36,4),MID(G36,4,2),LEFT(G36,2)),"")) -> 45686 | Q36: =--(COUNTIF($A$2:A36,A36)=1) -> 1 | R36: =IF(AND(Q36=1,I36<>"",ISNUMBER(I36),I36>=0),I36,"") -> 171.42
A37: TKT-00036 | B37: CUST-0971 | D37: Integration Issue | E37: Critical | F37: In Progress | G37: 2022-08-27 | J37: 4 | L37: Advaith Acharya | M37: In-App Chat | O37: FALSE | P37: =IFERROR(DATEVALUE(G37),IFERROR(DATE(RIGHT(G37,4),MID(G37,4,2),LEFT(G37,2)),"")) -> 44800 | Q37: =--(COUNTIF($A$2:A37,A37)=1) -> 1 | R37: =IF(AND(Q37=1,I37<>"",ISNUMBER(I37),I37>=0),I37,"")
A38: TKT-00037 | B38: CUST-1409 | D38: Billing & Payments | E38: Critical | F38: Resolved | G38: 2022-08-22 | H38: 44795 | I38: 6.22 | J38: 4 | K38: No | L38: Dayita Palan | M38: Phone | N38: 2 | O38: 0 | P38: =IFERROR(DATEVALUE(G38),IFERROR(DATE(RIGHT(G38,4),MID(G38,4,2),LEFT(G38,2)),"")) -> 44795 | Q38: =--(COUNTIF($A$2:A38,A38)=1) -> 1 | R38: =IF(AND(Q38=1,I38<>"",ISNUMBER(I38),I38>=0),I38,"") -> 6.22
A39: TKT-00038 | B39: CUST-1053 | D39: Data Discrepancy | E39: Low | F39: Resolved | G39: 2024-08-14 | H39: 45524 | I39: 158.09 | J39: 72 | K39: No | L39: Dipta Nadig | M39: Help Portal | N39: 4.9 | O39: False | P39: =IFERROR(DATEVALUE(G39),IFERROR(DATE(RIGHT(G39,4),MID(G39,4,2),LEFT(G39,2)),"")) -> 45518 | Q39: =--(COUNTIF($A$2:A39,A39)=1) -> 1 | R39: =IF(AND(Q39=1,I39<>"",ISNUMBER(I39),I39>=0),I39,"") -> 158.09
A40: TKT-00039 | B40: CUST-0797 | D40: Performance Issue | E40: Low | F40: In Progress | G40: 2024-08-26 | J40: 72 | L40: Eshana Soni | M40: Help Portal | O40: No | P40: =IFERROR(DATEVALUE(G40),IFERROR(DATE(RIGHT(G40,4),MID(G40,4,2),LEFT(G40,2)),"")) -> 45530 | Q40: =--(COUNTIF($A$2:A40,A40)=1) -> 1 | R40: =IF(AND(Q40=1,I40<>"",ISNUMBER(I40),I40>=0),I40,"")
...

Sheet Sales_Pipeline
A1: Deal_ID | B1: Customer_ID | C1: Campaign_ID | D1: Service_Line | E1: Sales_Stage | F1: Deal_Value_USD | G1: Deal_Source | H1: Sales_Rep_Name | I1: Created_Date | J1: Expected_Close_Date | K1: Closed_Date | L1: Days_to_Close | M1: Upsell_Flag | N1: Products_Sold | O1: Discount_Pct | P1: Region | Q1: Deal_Value_Clean | R1: Deal_Value_Unique
A2: DL-00001 | B2: CUST-1258 | D2: WorkHub Core | E2: Negotiation | F2: 7902 | G2: Paid Search | H2: Nihal Bhasin | I2: 2022-03-15 | J2: 44803 | M2: 0 | N2: 1 | O2: 3.6 | P2: Middle East | Q2: =IFERROR(IF(RIGHT(UPPER(TRIM(F2)),1)="K",VALUE(SUBSTITUTE(SUBSTITUTE(LEFT(TRIM(F2),LEN(TRIM(F2))-1),"$",""),",",""))*1000,IF(RIGHT(UPPER(TRIM(F2)),1)="M",VALUE(SUBSTITUTE(SUBSTITUTE(LEFT(TRIM(F2),LEN(TRIM(F2))-1),"$",""),",",""))*1000000,VALUE(SUBSTITUTE(SUBSTITUTE(TRIM(F2),"$",""),",","")))),"") -> 7902 | R2: =IF(COUNTIF($A$2:A2,A2)=1,Q2,"") -> 7902
A3: DL-00002 | B3: CUST-0652 | D3: WorkHub Core | E3: Proposal | F3: 3K | G3: LinkedIn Ads | H3: Ati Seshadri | I3: 2023-06-06 | J3: 45144 | M3: 0 | N3: 1 | O3: 12.6 | P3: Southeast Asia | Q3: =IFERROR(IF(RIGHT(UPPER(TRIM(F3)),1)="K",VALUE(SUBSTITUTE(SUBSTITUTE(LEFT(TRIM(F3),LEN(TRIM(F3))-1),"$",""),",",""))*1000,IF(RIGHT(UPPER(TRIM(F3)),1)="M",VALUE(SUBSTITUTE(SUBSTITUTE(LEFT(TRIM(F3),LEN(TRIM(F3))-1),"$",""),",",""))*1000000,VALUE(SUBSTITUTE(SUBSTITUTE(TRIM(F3),"$",""),",","")))),"") -> 3000 | R3: =IF(COUNTIF($A$2:A3,A3)=1,Q3,"") -> 3000
