Workbook

Sheet Customers
A1: Customer_ID | B1: Company_Name | C1: Industry | D1: Company_Size | E1: Customer_Tier | F1: Region | G1: Onboarding_Date | H1: Renewal_Status | I1: MRR_USD | J1: NPS_Score | K1: Subscribed_Plan | L1: CSM_Name | M1: Contract_Months | N1: Churn_Risk_Flag
A2: CUST-0001 | B2: Patla-Gaba | C2: Retail | D2: 1–50 | E2: Mid-Market | F2: Southeast Asia | G2: 2024-05-19 | H2: At Risk | I2: 911.36 | J2: 8 | K2: WorkHub Core | L2: Hemangini Lalla | M2: 24 | N2: 1
A3: CUST-0002 | B3: Pant-Kadakia | C3: BFSI | D3: 5000+ | E3: Enterprise | F3: Southeast Asia | G3: 2023-11-27 | H3: Active | I3: 10215.15 | J3: 9 | K3: WorkHub Pro | L3: Tripti Yadav | M3: 24 | N3: 0
A4: CUST-0003 | B4: Loke, Bora and Garg | C4: EdTech | D4: 1–50 | E4: Mid-Market | F4: South Asia | G4: 2024-01-24 | H4: Active | I4: 3723.34 | J4: 15 | K4: WorkHub Core | L4: Janaki Handa | M4: 12 | N4: 0
A5: CUST-0004 | B5: Konda, Gade and Shere | C5: Logistics | D5: 1001–5000 | E5: Mid-Market | F5: Southeast Asia | G5: 2022-05-06 | H5: Active | I5: 1352.5 | J5: 91 | K5: WorkHub Pro | L5: Lajita Chatterjee | M5: 36 | N5: 0
A6: CUST-0005 | B6: Madan-Kanda | C6: Healthcare | D6: 5000+ | E6: SMB | F6: East Africa | G6: 2022-10-25 | H6: At Risk | I6: 598.27 | K6: WorkHub Core | L6: Fariq Kaul | M6: 12 | N6: 1
A7: CUST-0006 | B7: Nair, Bhalla and Karnik | C7: EdTech | D7: 51–200 | E7: SMB | F7: Southeast Asia | G7: 2024-03-20 | H7: Active | I7: 500.59 | J7: 59 | K7: WorkHub Core | L7: Gagan Sami | M7: 12 | N7: 0
A8: CUST-0007 | B8: Mutti Group | C8: Government | D8: 5000+ | E8: SMB | F8: ANZ | G8: 2024-02-27 | H8: Churned | I8: 187.73 | J8: 40 | K8: WorkHub Core | L8: Janaki Handa | M8: 36 | N8: 1
A9: CUST-0008 | B9: Bhatti-Kakar | C9: Retail | D9: 5000+ | E9: Enterprise | F9: East Africa | G9: 2022-07-06 | H9: Active | I9: 11040.09 | J9: 7 | K9: WorkHub Enterprise | L9: Gayathri Chaudry | M9: 12 | N9: 0
A10: CUST-0009 | B10: Murty, Kala and Tata | C10: EdTech | D10: 201–1000 | E10: Mid-Market | F10: East Africa | G10: 2024-07-05 | H10: Active | I10: 1428.17 | J10: 70 | K10: WorkHub Core | L10: Lajita Mall | M10: 12 | N10: 0
A11: CUST-0010 | B11: Shanker-Dhar | C11: Retail | D11: 5000+ | E11: Enterprise | F11: East Africa | G11: 2022-06-07 | H11: Churned | I11: 16628.01 | K11: WorkHub Enterprise | L11: Aryan Maharaj | M11: 12 | N11: 1
A12: CUST-0011 | B12: Dewan-Koshy | C12: Real Estate | D12: 201–1000 | E12: Mid-Market | F12: Southeast Asia | G12: 2024-02-25 | H12: Churned | I12: 896.91 | J12: 80 | K12: WorkHub Core | L12: Chakradev Kari | M12: 12 | N12: 1
A13: CUST-0012 | B13: Yohannan, Lall and Sangha | C13: Media & Entertainment | D13: 201–1000 | E13: Mid-Market | F13: ANZ | G13: 2022-03-16 | H13: Active | I13: 2129.99 | J13: 59 | K13: WorkHub Pro | L13: Lajita Chatterjee | M13: 36 | N13: 0
A14: CUST-0013 | B14: Rastogi, Pathak and Kanda | C14: Manufacturing | D14: 1001–5000 | E14: Enterprise | F14: Southeast Asia | G14: 2024-02-18 | H14: Churned | I14: 8467.62 | K14: WorkHub Pro | L14: Nathaniel Sami | M14: 12 | N14: 1
A15: CUST-0014 | B15: Upadhyay Group | C15: Logistics | D15: 1001–5000 | E15: Enterprise | F15: East Africa | G15: 2023-03-05 | H15: At Risk | I15: 6235.8 | J15: 41 | K15: WorkHub Pro | L15: Saumya Mall | M15: 12 | N15: 1
A16: CUST-0015 | B16: Batta Inc | C16: Telecom | D16: 1001–5000 | E16: Mid-Market | F16: ANZ | G16: 2024-06-19 | H16: Active | I16: 3824.74 | J16: 64 | K16: WorkHub Pro | L16: Saumya Mall | M16: 36 | N16: 0
A17: CUST-0016 | B17: Dutta Ltd | C17: BFSI | D17: 201–1000 | E17: Mid-Market | F17: ANZ | G17: 2023-09-04 | H17: Churned | I17: 2305.88 | K17: WorkHub Pro | L17: Kritika Brar | M17: 12 | N17: 1
A18: CUST-0017 | B18: Bhatt-Rajan | C18: Manufacturing | D18: 1001–5000 | E18: Mid-Market | F18: Middle East | G18: 2022-02-16 | H18: Churned | I18: 1422.9 | J18: 70 | K18: WorkHub Core | L18: Fariq Kaul | M18: 24 | N18: 1
A19: CUST-0018 | B19: Sidhu-Wadhwa | C19: Logistics | D19: 5000+ | E19: Mid-Market | F19: East Africa | G19: 2022-05-02 | H19: Active | I19: 1994.23 | J19: 43 | K19: WorkHub Core | L19: Viraj Tiwari | M19: 12 | N19: 0
A20: CUST-0019 | B20: Apte-Contractor | C20: Media & Entertainment | D20: 5000+ | E20: SMB | F20: South Asia | G20: 16/02/2022 | H20: Churned | I20: 662.78 | J20: 66 | K20: WorkHub Core | L20: Lajita Chatterjee | M20: 36 | N20: 1
A21: CUST-0020 | B21: Yadav, Loke and Oak | C21: Media & Entertainment | D21: 5000+ | E21: Enterprise | F21: Middle East | G21: 2023-08-31 | H21: At Risk | I21: 11452.76 | J21: 90 | K21: WorkHub Pro | L21: Aryan Maharaj | M21: 24 | N21: 1
A22: CUST-0021 | B22: Memon Group | C22: Healthcare | D22: 1001–5000 | E22: SMB | F22: East Africa | G22: 2022-11-12 | H22: Churned | I22: 581.63 | K22: WorkHub Core | L22: Nathaniel Sami | M22: 36 | N22: 1
A23: CUST-0022 | B23: Setty Inc | C23: Government | D23: 51–200 | E23: SMB | F23: East Africa | G23: 2023-10-07 | H23: At Risk | I23: 366.13 | J23: 87 | K23: WorkHub Core | L23: Saumya Mall | M23: 12 | N23: 1
A24: CUST-0023 | B24: Lall, Tella and Gokhale | C24: Media & Entertainment | D24: 51–200 | E24: Mid-Market | F24: ANZ | G24: 2023-12-09 | H24: Active | I24: 2756.73 | J24: 60 | K24: WorkHub Pro | L24: Viraj Tiwari | M24: 36 | N24: 0
A25: CUST-0024 | B25: Cherian, Misra and Tripathi | C25: Manufacturing | D25: 1001–5000 | E25: Enterprise | F25: East Africa | G25: 2023-01-21 | H25: Active | I25: 16769.74 | J25: 43 | K25: WorkHub Pro | L25: Chakradev Kari | M25: 12 | N25: 0
A26: CUST-0025 | B26: Issac, Dua and Prakash | C26: Logistics | D26: 5000+ | E26: SMB | F26: Middle East | G26: 2022-08-19 | H26: Renewed | I26: 639.82 | J26: 90 | K26: WorkHub Core | L26: Lajita Chatterjee | M26: 24 | N26: 0
A27: CUST-0026 | B27: Zacharia PLC | C27: Logistics | D27: 201–1000 | E27: Mid-Market | F27: South Asia | G27: 2023-08-11 | H27: Active | I27: 3936.51 | J27: 44 | K27: WorkHub Pro | L27: Gayathri Chaudry | M27: 12 | N27: 0
A28: CUST-0027 | B28: Naik Group | C28: Healthcare | D28: 201–1000 | E28: Enterprise | F28: ANZ | G28: 2023-11-03 | H28: Active | I28: 6828.95 | J28: 68 | K28: WorkHub Pro | L28: Viraj Tiwari | M28: 12 | N28: 0
A29: CUST-0028 | B29: Choudhury LLC | C29: Real Estate | D29: 51–200 | E29: Enterprise | F29: Southeast Asia | G29: 2022-02-21 | H29: Active | I29: 12931.22 | K29: WorkHub Pro | L29: Chakradev Kari | M29: 12 | N29: 0
A30: CUST-0029 | B30: Khatri-Bhardwaj | C30: Retail | D30: 1–50 | E30: SMB | F30: East Africa | G30: 2024-09-28 | H30: Active | I30: 754.52 | J30: 60 | K30: WorkHub Core | L30: Gayathri Chaudry | M30: 24 | N30: 0
A31: CUST-0030 | B31: Brar Inc | C31: BFSI | D31: 1–50 | E31: Mid-Market | F31: East Africa | G31: 2022-08-26 | H31: Churned | I31: 3797.34 | J31: 22 | K31: WorkHub Pro | L31: Udant Dewan | M31: 24 | N31: 1
A32: CUST-0031 | B32: Sunder, Biswas and Walia | C32: Retail | D32: 201–1000 | E32: SMB | F32: South Asia | G32: 2022-01-10 | H32: Churned | I32: 749.92 | J32: 42 | K32: WorkHub Core | L32: Viraj Tiwari | M32: 36 | N32: 1
A33: CUST-0032 | B33: Dave Ltd | C33: EdTech | D33: 1–50 | E33: SMB | F33: Middle East | G33: 2022-06-16 | H33: Churned | I33: 603.02 | J33: 1 | K33: WorkHub Core | L33: Saumya Mall | M33: 12 | N33: 1
A34: CUST-0033 | B34: Gandhi-Lanka | C34: Media & Entertainment | D34: 1001–5000 | E34: Mid-Market | F34: East Africa | G34: 02/12/2022 | H34: Churned | I34: 1391.3 | J34: 17 | K34: WorkHub Pro | L34: Aryan Maharaj | M34: 24 | N34: 1
A35: CUST-0034 | B35: Sampath, Kakar and Zacharia | C35: Government | D35: 201–1000 | E35: SMB | F35: Middle East | G35: 2022-11-06 | H35: Churned | I35: 283.09 | J35: 46 | K35: WorkHub Core | L35: Ayushman Chander | M35: 24 | N35: 1
A36: CUST-0035 | B36: Iyer, Muni and Rastogi | C36: Media & Entertainment | D36: 5000+ | E36: Mid-Market | F36: Middle East | G36: 08/12/2023 | H36: Renewed | I36: 1744.12 | J36: 78 | K36: WorkHub Pro | L36: Chakradev Kari | M36: 12 | N36: 0
A37: CUST-0036 | B37: Prakash, Sarma and Varughese | C37: Real Estate | D37: 201–1000 | E37: Mid-Market | F37: ANZ | G37: 2023-12-20 | H37: Active | I37: 2520.06 | J37: 85 | K37: WorkHub Pro | L37: Gagan Sami | M37: 36 | N37: 0
A38: CUST-0037 | B38: Dara-Kota | C38: Manufacturing | D38: 1–50 | E38: SMB | F38: East Africa | G38: 25/04/2022 | H38: Active | I38: 453.84 | J38: 73 | K38: WorkHub Core | L38: Lajita Chatterjee | M38: 36 | N38: 0
A39: CUST-0038 | B39: Bhatt LLC | C39: EdTech | D39: 5000+ | E39: Mid-Market | F39: ANZ | G39: 2022-04-04 | H39: Active | I39: 978.03 | J39: 16 | K39: WorkHub Core | L39: Udant Dewan | M39: 36 | N39: 0
A40: CUST-0039 | B40: Karpe PLC | C40: Logistics | D40: 1–50 | E40: SMB | F40: ANZ | G40: 2022-09-18 | H40: At Risk | I40: 504.82 | J40: 5 | K40: WorkHub Core | L40: Lajita Mall | M40: 12 | N40: 1
...

Sheet  Raw Data 
A1: Deal_ID | B1: Customer_ID | C1: Campaign_ID | D1: Service_Line | E1: Sales_Stage | F1: Deal_Value_USD | G1: Deal_Source | H1: Sales_Rep_Name | I1: Created_Date | J1: Expected_Close_Date | K1: Closed_Date | L1: Days_to_Close | M1: Upsell_Flag | N1: Products_Sold | O1: Discount_Pct | P1: Region
A2: DL-00001 | B2: CUST-1258 | D2: WorkHub Core | E2: Negotiation | F2: 7902 | G2: Paid Search | H2: Nihal Bhasin | I2: 2022-03-15 | J2: 44803 | M2: 0 | N2: 1 | O2: 3.6 | P2: Middle East
A3: DL-00002 | B3: CUST-0652 | D3: WorkHub Core | E3: Proposal | F3: 3000 | G3: LinkedIn Ads | H3: Ati Seshadri | I3: 2023-06-06 | J3: 45144 | M3: 0 | N3: 1 | O3: 12.6 | P3: Southeast Asia
A4: DL-00003 | B4: CUST-0657 | C4: CMP-258 | D4: WorkHub Enterprise | E4: Negotiation | F4: 81996 | G4: Product-Led Signup | H4: Karan Karnik | I4: 2023-02-05 | J4: 45054 | M4: 0 | N4: 1 | P4: ANZ
A5: DL-00004 | B5: CUST-1189 | D5: WorkHub Enterprise | E5: Prospecting | F5: 151127 | G5: Event | H5: rachit lall | I5: 2024-02-06 | J5: 45472 | M5: 0 | N5: 1 | O5: 2.5 | P5: ANZ
A6: DL-00005 | B6: CUST-1278 | C6: CMP-184 | D6: WorkHub Pro | E6: Demo | F6: 19891 | G6: Webinar | H6: Ati Seshadri | I6: 2023-04-23 | J6: 45181 | M6: 0 | N6: 1 | O6: 27.8 | P6: South Asia
A7: DL-00006 | B7: CUST-0818 | D7: WorkHub Enterprise | E7: Proposal | F7: 73353 | G7: LinkedIn Ads | H7: Jairaj Panchal | I7: 2022-11-19 | J7: 44917 | M7: 0 | N7: 1 | O7: 30.3 | P7: Southeast Asia
A8: DL-00007 | B8: CUST-0647 | D8: API Access | E8: Demo | F8: 7000 | G8: Product-Led Signup | H8: Anamika Keer | I8: 2024-04-16 | J8: 45488 | M8: 0 | N8: 1 | P8: Middle East
A9: DL-00008 | B9: CUST-0056 | D9: API Access | E9: Demo | F9: 4000 | G9: Webinar | H9: Karan Karnik | I9: 24/03/2022 | J9: 44716 | M9: 0 | N9: 1 | O9: 5.5 | P9: Southeast Asia
A10: DL-00009 | B10: CUST-0355 | C10: CMP-054 | D10: WorkHub Core | E10: Demo | F10: 8506 | G10: Partner Referral | H10: Shivani Natt | I10: 2022-11-11 | J10: 45028 | M10: 0 | N10: 1 | O10: 14.1 | P10: South Asia
A11: DL-00010 | B11: CUST-0537 | C11: CMP-327 | D11: API Access | E11: Proposal | F11: 4469 | G11: Product-Led Signup | H11: Mason Solanki | I11: 2022-01-02 | J11: 44723 | M11: 0 | N11: 1 | O11: 32 | P11: Southeast Asia
A12: DL-00011 | B12: CUST-1067 | C12: CMP-224 | D12: WorkHub Enterprise | E12: Closed Won | F12: 178212 | G12: Product-Led Signup | H12: Owen Mane | I12: 29/09/2023 | J12: 45324 | K12: 45273 | L12: 75 | M12: 1 | N12: 2 | O12: 3.9 | P12: Southeast Asia
A13: DL-00012 | B13: CUST-0375 | D13: WorkHub Core | E13: Demo | F13: 3564 | G13: Paid Search | H13: Amruta Sinha | I13: 2022-08-19 | J13: 44937 | M13: 0 | N13: 1 | O13: 19.9 | P13: East Africa
A14: DL-00013 | B14: CUST-0833 | C14: CMP-378 | D14: API Access | E14: Negotiation | F14: 5862 | G14: Partner Referral | H14: Hemangini Bahri | I14: 2023-02-12 | J14: 44998 | M14: 0 | N14: 1 | O14: 15.1 | P14: Southeast Asia
A15: DL-00014 | B15: CUST-0128 | C15: CMP-121 | D15: WorkHub Core | E15: Demo | F15: 1000 | G15: Webinar | H15: Ati Seshadri | I15: 2022-07-17 | J15: 44857 | M15: 0 | N15: 1 | O15: 9.5 | P15: South Asia
A16: DL-00015 | B16: CUST-1133 | C16: CMP-091 | D16: WorkHub Pro | E16: Closed Lost | F16: 24887 | G16: LinkedIn Ads | H16: Ekta Uppal | I16: 2024-07-12 | J16: 45541 | K16: 45616 | L16: 131 | M16: 0 | N16: 1 | O16: 32.7 | P16: Southeast Asia
A17: DL-00016 | B17: CUST-1028 | C17: CMP-127 | D17: API Access | E17: Closed Lost | F17: 10459 | G17: Webinar | H17: Karan Karnik | I17: 2024-11-01 | J17: 45773 | K17: 45720 | L17: 123 | M17: 0 | N17: 1 | O17: 6.2 | P17: Middle East
A18: DL-00017 | B18: CUST-0223 | C18: CMP-378 | D18: WorkHub Core | E18: Closed Lost | F18: 7222 | G18: Webinar | H18: Kashish Patla | I18: 2023-04-08 | J18: 45177 | K18: 45101 | L18: 77 | M18: 0 | N18: 1 | O18: 12.2 | P18: South Asia
A19: DL-00018 | B19: CUST-0667 | C19: CMP-335 | D19: WorkHub Core | E19: Demo | F19: 8134 | G19: Event | H19: Aachal Soni | I19: 2024-01-29 | J19: 45497 | M19: 0 | N19: 1 | P19: Southeast Asia
A20: DL-00019 | B20: CUST-1273 | C20: CMP-339 | D20: WorkHub Pro | E20: Proposal | F20: 46846 | G20: Event | H20: Champak Rao | I20: 2023-12-23 | J20: 45434 | M20: 0 | N20: 1 | O20: 18.9 | P20: South Asia
A21: DL-00020 | B21: CUST-1499 | C21: CMP-140 | D21: WorkHub Pro | E21: Closed Won | F21: 33087 | G21: Product-Led Signup | H21: Krish Varughese | I21: 2022-12-16 | J21: 44950 | K21: 45045 | L21: 134 | M21: 1 | N21: 2 | O21: 12 | P21: South Asia
A22: DL-00021 | B22: CUST-1485 | C22: CMP-012 | D22: WorkHub Enterprise | E22: Closed Lost | F22: 119072 | G22: Inbound Organic | H22: Nihal Bhasin | I22: 2024-04-23 | J22: 45497 | K22: 45537 | L22: 132 | M22: 0 | N22: 1 | O22: 20.1 | P22: East Africa
A23: DL-00022 | B23: CUST-0937 | D23: WorkHub Enterprise | E23: Negotiation | F23: 116146 | G23: Event | H23: Lakshmi Hayre | I23: 2023-08-06 | J23: 45289 | M23: 0 | N23: 1 | O23: 21.3 | P23: ANZ
A24: DL-00023 | B24: CUST-0939 | D24: API Access | E24: Closed Lost | F24: 23944 | G24: Cold Outreach | H24: Karan Karnik | I24: 2022-08-07 | J24: 44944 | K24: 44867 | L24: 87 | M24: 0 | N24: 1 | P24: East Africa
A25: DL-00024 | B25: CUST-0021 | C25: CMP-130 | D25: WorkHub Enterprise | E25: Closed Lost | F25: 115000 | G25: Paid Search | H25: Amruta Sinha | I25: 2024-03-23 | K25: 45533 | L25: 159 | M25: 0 | N25: 1 | O25: 6.3 | P25: South Asia
A26: DL-00025 | B26: CUST-0002 | C26: CMP-055 | D26: API Access | E26: Closed Lost | F26: 17202 | G26: Content Download | H26: Karan Karnik | I26: 2023-09-17 | J26: 45261 | K26: 45327 | L26: 141 | M26: 0 | N26: 1 | O26: 9.2 | P26: ANZ
A27: DL-00026 | B27: CUST-0485 | C27: CMP-399 | D27: WorkHub Core | E27: Qualification | F27: 1586 | G27: Event | H27: krish varughese | I27: 12/03/2023 | J27: 45111 | M27: 0 | N27: 1 | O27: 14.1 | P27: Southeast Asia
A28: DL-00027 | B28: CUST-0733 | D28: Analytics Add-on | E28: Demo | F28: 8000 | G28: Content Download | H28: Lakshmi Hayre | I28: 2023-08-26 | J28: 45307 | M28: 0 | N28: 1 | O28: 32 | P28: ANZ
A29: DL-00028 | B29: CUST-1317 | D29: WorkHub Core | E29: Prospecting | F29: 8919 | G29: Webinar | H29: Champak Rao | I29: 2023-07-10 | J29: 45196 | M29: 0 | N29: 1 | P29: Middle East
A30: DL-00029 | B30: CUST-1145 | C30: CMP-218 | D30: Analytics Add-on | E30: Closed Won | F30: 11849 | G30: Cold Outreach | H30: ati seshadri | I30: 2022-10-18 | J30: 44949 | K30: 45028 | L30: 176 | M30: 0 | N30: 1 | O30: 30.5 | P30: Southeast Asia
A31: DL-00030 | B31: CUST-0371 | C31: CMP-351 | D31: WorkHub Core | E31: Negotiation | F31: 7862 | G31: Cold Outreach | H31: Anamika Keer | I31: 2024-06-19 | J31: 45555 | M31: 0 | N31: 1 | O31: 13.6 | P31: Middle East
A32: DL-00031 | B32: CUST-1231 | D32: Analytics Add-on | E32: Demo | F32: 14033 | G32: Paid Search | H32: Anamika Keer | I32: 2022-06-17 | J32: 44833 | M32: 0 | N32: 1 | O32: 5.8 | P32: Southeast Asia
A33: DL-00032 | B33: CUST-1349 | C33: CMP-285 | D33: WorkHub Pro | E33: Closed Lost | F33: 28595 | G33: Paid Search | H33: Aachal Soni | I33: 2024-08-06 | J33: 45594 | K33: 45669 | L33: 159 | M33: 0 | N33: 1 | O33: 25.6 | P33: Middle East
A34: DL-00033 | B34: CUST-0351 | D34: WorkHub Pro | E34: Negotiation | F34: 13494 | G34: Partner Referral | H34: Ati Seshadri | I34: 2023-10-03 | J34: 45345 | M34: 0 | N34: 1 | P34: South Asia
A35: DL-00034 | B35: CUST-1305 | C35: CMP-375 | D35: WorkHub Core | E35: Demo | F35: 6564 | G35: Paid Search | H35: Lakshmi Hayre | I35: 2024-01-20 | J35: 45362 | M35: 0 | N35: 1 | O35: 30.6 | P35: ANZ
A36: DL-00035 | B36: CUST-1190 | C36: CMP-036 | D36: WorkHub Enterprise | E36: Closed Won | F36: 104006 | G36: Event | H36: Karan Karnik | I36: 2022-03-17 | K36: 44706 | L36: 69 | M36: 1 | N36: 2 | O36: 14.7 | P36: Southeast Asia
A37: DL-00036 | B37: CUST-1068 | C37: CMP-095 | D37: API Access | E37: Closed Lost | F37: 10794 | G37: Product-Led Signup | H37: Amruta Sinha | I37: 2022-05-20 | J37: 44855 | K37: 44723 | L37: 22 | M37: 0 | N37: 1 | O37: 10 | P37: South Asia
A38: DL-00037 | B38: CUST-0251 | D38: Analytics Add-on | E38: Closed Won | F38: 8191 | G38: Product-Led Signup | H38: Patrick Sama | I38: 2023-04-09 | J38: 45171 | K38: 45176 | L38: 151 | M38: 0 | N38: 1 | O38: 3.8 | P38: Middle East
A39: DL-00038 | B39: CUST-1017 | D39: WorkHub Core | E39: Closed Won | F39: 9490 | G39: Event | H39: Vidhi Mital | I39: 14/05/2022 | J39: 44811 | K39: 44869 | L39: 174 | M39: 0 | N39: 1 | O39: 31.1 | P39: Middle East
A40: DL-00039 | B40: CUST-1204 | C40: CMP-049 | D40: API Access | E40: Negotiation | F40: 8249 | G40: Inbound Organic | H40: Amruta Sinha | I40: 2024-09-09 | J40: 45618 | M40: 0 | N40: 1 | O40: 23.9 | P40: East Africa
...

Sheet Cleaned Data
A1: Deal_ID | B1: Customer_ID | C1: Campaign_ID | D1: Service_Line | E1: Sales_Stage | F1: Deal_Value_USD | G1: Deal_Value_USD Clean | H1: Deal_Source | I1: Sales_Rep_Name | J1: Sales_Rep_Name_Clean | K1: Created_Date | L1: Created_Date_Clean | M1: Expected_Close_Date | N1: Expected_Close_Date_Clean | O1: Closed_Date | P1: Closed_Date_Clean | Q1: Days_to_Close | R1: Upsell_Flag | S1: Products_Sold | T1: Discount_Pct | U1: Region | V1: Deal_Value_USD_Normalized | W1: Deal_Status | X1: Customer_Tier | Y1: Closed_Deal_Flag | Z1: Days_Late | AA1: Missed_30_Days
A2: DL-00001 | B2: CUST-1258 | D2: WorkHub Core | E2: Negotiation | F2: 7902 | G2: =IF(F2="","",IF(RIGHT(UPPER(SUBSTITUTE(SUBSTITUTE(SUBSTITUTE(TRIM(F2),"$",""),",","")," ","")),1)="K",VALUE(LEFT(UPPER(SUBSTITUTE(SUBSTITUTE(SUBSTITUTE(TRIM(F2),"$",""),",","")," ","")),LEN(UPPER(SUBSTITUTE(SUBSTITUTE(SUBSTITUTE(TRIM(F2),"$",""),",","")," ","")))-1))*1000,IF(RIGHT(UPPER(SUBSTITUTE(SUBSTITUTE(SUBSTITUTE(TRIM(F2),"$",""),",","")," ","")),1)="M",VALUE(LEFT(UPPER(SUBSTITUTE(SUBSTITUTE(SUBSTITUTE(TRIM(F2),"$",""),",","")," ","")),LEN(UPPER(SUBSTITUTE(SUBSTITUTE(SUBSTITUTE(TRIM(F2),"$",""),",","")," ","")))-1))*1000000,VALUE(SUBSTITUTE(SUBSTITUTE(SUBSTITUTE(TRIM(F2),"$",""),",","")," ",""))))) -> 7902 | H2: Paid Search | I2: Nihal Bhasin | J2: =PROPER(TRIM(I2)) -> Nihal Bhasin | K2: 2022-03-15 | L2: =IF(K2="","",IF(ISNUMBER(K2),K2,IF(ISNUMBER(SEARCH("/",K2)),DATE(VALUE(RIGHT(K2,4)),VALUE(MID(K2,4,2)),VALUE(LEFT(K2,2))),DATE(VALUE(LEFT(K2,4)),VALUE(MID(K2,6,2)),VALUE(RIGHT(K2,2)))))) -> 44635 | M2: 44803 | N2: =IF(M2="","",IF(ISNUMBER(M2),M2,IF(ISNUMBER(SEARCH("/",M2)),DATE(VALUE(RIGHT(M2,4)),VALUE(MID(M2,4,2)),VALUE(LEFT(M2,2))),DATE(VALUE(LEFT(M2,4)),VALUE(MID(M2,6,2)),VALUE(RIGHT(M2,2)))))) -> 44803 | P2: =IF(O2="","",IF(ISNUMBER(O2),O2,DATE(VALUE(LEFT(O2,4)),VALUE(MID(O2,6,2)),VALUE(RIGHT(O2,2))))) | R2: 0 | S2: 1 | T2: 3.6 | U2: Middle East | V2: 7902 | W2: =IF(E2="","",IF(E2="Closed Won","Won",IF(E2="Closed Lost","Lost","Open"))) -> Open | X2: =_xlfn.XLOOKUP(B2,'Customers'!A:A,'Customers'!E:E,"") -> SMB | Y2: =IF(OR(W2="Won",W2="Lost"),1,0) -> 0 | Z2: =IF(OR(N2="",P2=""),"",P2-N2) | AA2: =IF(AND(Y2=1,Z2>30),1,0) -> 0
A3: DL-00002 | B3: CUST-0652 | D3: WorkHub Core | E3: Proposal | F3: 3K | G3: =IF(F3="","",IF(RIGHT(UPPER(SUBSTITUTE(SUBSTITUTE(SUBSTITUTE(TRIM(F3),"$",""),",","")," ","")),1)="K",VALUE(LEFT(UPPER(SUBSTITUTE(SUBSTITUTE(SUBSTITUTE(TRIM(F3),"$",""),",","")," ","")),LEN(UPPER(SUBSTITUTE(SUBSTITUTE(SUBSTITUTE(TRIM(F3),"$",""),",","")," ","")))-1))*1000,IF(RIGHT(UPPER(SUBSTITUTE(SUBSTITUTE(SUBSTITUTE(TRIM(F3),"$",""),",","")," ","")),1)="M",VALUE(LEFT(UPPER(SUBSTITUTE(SUBSTITUTE(SUBSTITUTE(TRIM(F3),"$",""),",","")," ","")),LEN(UPPER(SUBSTITUTE(SUBSTITUTE(SUBSTITUTE(TRIM(F3),"$",""),",","")," ","")))-1))*1000000,VALUE(SUBSTITUTE(SUBSTITUTE(SUBSTITUTE(TRIM(F3),"$",""),",","")," ",""))))) -> 3000 | H3: LinkedIn Ads | I3: Ati Seshadri | J3: =PROPER(TRIM(I3)) -> Ati Seshadri | K3: 2023-06-06 | L3: =IF(K3="","",IF(ISNUMBER(K3),K3,IF(ISNUMBER(SEARCH("/",K3)),DATE(VALUE(RIGHT(K3,4)),VALUE(MID(K3,4,2)),VALUE(LEFT(K3,2))),DATE(VALUE(LEFT(K3,4)),VALUE(MID(K3,6,2)),VALUE(RIGHT(K3,2)))))) -> 45083 | M3: 45144 | N3: =IF(M3="","",IF(ISNUMBER(M3),M3,IF(ISNUMBER(SEARCH("/",M3)),DATE(VALUE(RIGHT(M3,4)),VALUE(MID(M3,4,2)),VALUE(LEFT(M3,2))),DATE(VALUE(LEFT(M3,4)),VALUE(MID(M3,6,2)),VALUE(RIGHT(M3,2)))))) -> 45144 | P3: =IF(O3="","",IF(ISNUMBER(O3),O3,DATE(VALUE(LEFT(O3,4)),VALUE(MID(O3,6,2)),VALUE(RIGHT(O3,2))))) | R3: 0 | S3: 1 | T3: 12.6 | U3: Southeast Asia | V3: 3000 | W3: =IF(E3="","",IF(E3="Closed Won","Won",IF(E3="Closed Lost","Lost","Open"))) -> Open | X3: =_xlfn.XLOOKUP(B3,'Customers'!A:A,'Customers'!E:E,"") -> Enterprise | Y3: =IF(OR(W3="Won",W3="Lost"),1,0) -> 0 | Z3: =IF(OR(N3="",P3=""),"",P3-N3) | AA3: =IF(AND(Y3=1,Z3>30),1,0) -> 0
A4: DL-00003 | B4: CUST-0657 | C4: CMP-258 | D4: WorkHub Enterprise | E4: Negotiation | F4: $81,996 | G4: =IF(F4="","",IF(RIGHT(UPPER(SUBSTITUTE(SUBSTITUTE(SUBSTITUTE(TRIM(F4),"$",""),",","")," ","")),1)="K",VALUE(LEFT(UPPER(SUBSTITUTE(SUBSTITUTE(SUBSTITUTE(TRIM(F4),"$",""),",","")," ","")),LEN(UPPER(SUBSTITUTE(SUBSTITUTE(SUBSTITUTE(TRIM(F4),"$",""),",","")," ","")))-1))*1000,IF(RIGHT(UPPER(SUBSTITUTE(SUBSTITUTE(SUBSTITUTE(TRIM(F4),"$",""),",","")," ","")),1)="M",VALUE(LEFT(UPPER(SUBSTITUTE(SUBSTITUTE(SUBSTITUTE(TRIM(F4),"$",""),",","")," ","")),LEN(UPPER(SUBSTITUTE(SUBSTITUTE(SUBSTITUTE(TRIM(F4),"$",""),",","")," ","")))-1))*1000000,VALUE(SUBSTITUTE(SUBSTITUTE(SUBSTITUTE(TRIM(F4),"$",""),",","")," ",""))))) -> 81996 | H4: Product-Led Signup | I4: Karan Karnik | J4: =PROPER(TRIM(I4)) -> Karan Karnik | K4: 2023-02-05 | L4: =IF(K4="","",IF(ISNUMBER(K4),K4,IF(ISNUMBER(SEARCH("/",K4)),DATE(VALUE(RIGHT(K4,4)),VALUE(MID(K4,4,2)),VALUE(LEFT(K4,2))),DATE(VALUE(LEFT(K4,4)),VALUE(MID(K4,6,2)),VALUE(RIGHT(K4,2)))))) -> 44962 | M4: 45054 | N4: =IF(M4="","",IF(ISNUMBER(M4),M4,IF(ISNUMBER(SEARCH("/",M4)),DATE(VALUE(RIGHT(M4,4)),VALUE(MID(M4,4,2)),VALUE(LEFT(M4,2))),DATE(VALUE(LEFT(M4,4)),VALUE(MID(M4,6,2)),VALUE(RIGHT(M4,2)))))) -> 45054 | P4: =IF(O4="","",IF(ISNUMBER(O4),O4,DATE(VALUE(LEFT(O4,4)),VALUE(MID(O4,6,2)),VALUE(RIGHT(O4,2))))) | R4: 0 | S4: 1 | U4: ANZ | V4: 81996 | W4: =IF(E4="","",IF(E4="Closed Won","Won",IF(E4="Closed Lost","Lost","Open"))) -> Open | X4: =_xlfn.XLOOKUP(B4,'Customers'!A:A,'Customers'!E:E,"") -> Enterprise | Y4: =IF(OR(W4="Won",W4="Lost"),1,0) -> 0 | Z4: =IF(OR(N4="",P4=""),"",P4-N4) | AA4: =IF(AND(Y4=1,Z4>30),1,0) -> 0
A5: DL-00004 | B5: CUST-1189 | D5: WorkHub Enterprise | E5: Prospecting | F5: $151,127 | G5: =IF(F5="","",IF(RIGHT(UPPER(SUBSTITUTE(SUBSTITUTE(SUBSTITUTE(TRIM(F5),"$",""),",","")," ","")),1)="K",VALUE(LEFT(UPPER(SUBSTITUTE(SUBSTITUTE(SUBSTITUTE(TRIM(F5),"$",""),",","")," ","")),LEN(UPPER(SUBSTITUTE(SUBSTITUTE(SUBSTITUTE(TRIM(F5),"$",""),",","")," ","")))-1))*1000,IF(RIGHT(UPPER(SUBSTITUTE(SUBSTITUTE(SUBSTITUTE(TRIM(F5),"$",""),",","")," ","")),1)="M",VALUE(LEFT(UPPER(SUBSTITUTE(SUBSTITUTE(SUBSTITUTE(TRIM(F5),"$",""),",","")," ","")),LEN(UPPER(SUBSTITUTE(SUBSTITUTE(SUBSTITUTE(TRIM(F5),"$",""),",","")," ","")))-1))*1000000,VALUE(SUBSTITUTE(SUBSTITUTE(SUBSTITUTE(TRIM(F5),"$",""),",","")," ",""))))) -> 151127 | H5: Event | I5: rachit lall | J5: =PROPER(TRIM(I5)) -> Rachit Lall | K5: 2024-02-06 | L5: =IF(K5="","",IF(ISNUMBER(K5),K5,IF(ISNUMBER(SEARCH("/",K5)),DATE(VALUE(RIGHT(K5,4)),VALUE(MID(K5,4,2)),VALUE(LEFT(K5,2))),DATE(VALUE(LEFT(K5,4)),VALUE(MID(K5,6,2)),VALUE(RIGHT(K5,2)))))) -> 45328 | M5: 45472 | N5: =IF(M5="","",IF(ISNUMBER(M5),M5,IF(ISNUMBER(SEARCH("/",M5)),DATE(VALUE(RIGHT(M5,4)),VALUE(MID(M5,4,2)),VALUE(LEFT(M5,2))),DATE(VALUE(LEFT(M5,4)),VALUE(MID(M5,6,2)),VALUE(RIGHT(M5,2)))))) -> 45472 | P5: =IF(O5="","",IF(ISNUMBER(O5),O5,DATE(VALUE(LEFT(O5,4)),VALUE(MID(O5,6,2)),VALUE(RIGHT(O5,2))))) | R5: 0 | S5: 1 | T5: 2.5 | U5: ANZ | V5: 151127 | W5: =IF(E5="","",IF(E5="Closed Won","Won",IF(E5="Closed Lost","Lost","Open"))) -> Open | X5: =_xlfn.XLOOKUP(B5,'Customers'!A:A,'Customers'!E:E,"") -> Mid-Market | Y5: =IF(OR(W5="Won",W5="Lost"),1,0) -> 0 | Z5: =IF(OR(N5="",P5=""),"",P5-N5) | AA5: =IF(AND(Y5=1,Z5>30),1,0) -> 0
A6: DL-00005 | B6: CUST-1278 | C6: CMP-184 | D6: WorkHub Pro | E6: Demo | F6: 19,891 | G6: =IF(F6="","",IF(RIGHT(UPPER(SUBSTITUTE(SUBSTITUTE(SUBSTITUTE(TRIM(F6),"$",""),",","")," ","")),1)="K",VALUE(LEFT(UPPER(SUBSTITUTE(SUBSTITUTE(SUBSTITUTE(TRIM(F6),"$",""),",","")," ","")),LEN(UPPER(SUBSTITUTE(SUBSTITUTE(SUBSTITUTE(TRIM(F6),"$",""),",","")," ","")))-1))*1000,IF(RIGHT(UPPER(SUBSTITUTE(SUBSTITUTE(SUBSTITUTE(TRIM(F6),"$",""),",","")," ","")),1)="M",VALUE(LEFT(UPPER(SUBSTITUTE(SUBSTITUTE(SUBSTITUTE(TRIM(F6),"$",""),",","")," ","")),LEN(UPPER(SUBSTITUTE(SUBSTITUTE(SUBSTITUTE(TRIM(F6),"$",""),",","")," ","")))-1))*1000000,VALUE(SUBSTITUTE(SUBSTITUTE(SUBSTITUTE(TRIM(F6),"$",""),",","")," ",""))))) -> 19891 | H6: Webinar | I6: Ati Seshadri | J6: =PROPER(TRIM(I6)) -> Ati Seshadri | K6: 2023-04-23 | L6: =IF(K6="","",IF(ISNUMBER(K6),K6,IF(ISNUMBER(SEARCH("/",K6)),DATE(VALUE(RIGHT(K6,4)),VALUE(MID(K6,4,2)),VALUE(LEFT(K6,2))),DATE(VALUE(LEFT(K6,4)),VALUE(MID(K6,6,2)),VALUE(RIGHT(K6,2)))))) -> 45039 | M6: 45181 | N6: =IF(M6="","",IF(ISNUMBER(M6),M6,IF(ISNUMBER(SEARCH("/",M6)),DATE(VALUE(RIGHT(M6,4)),VALUE(MID(M6,4,2)),VALUE(LEFT(M6,2))),DATE(VALUE(LEFT(M6,4)),VALUE(MID(M6,6,2)),VALUE(RIGHT(M6,2)))))) -> 45181 | P6: =IF(O6="","",IF(ISNUMBER(O6),O6,DATE(VALUE(LEFT(O6,4)),VALUE(MID(O6,6,2)),VALUE(RIGHT(O6,2))))) | R6: 0 | S6: 1 | T6: 27.8 | U6: South Asia | V6: 19891 | W6: =IF(E6="","",IF(E6="Closed Won","Won",IF(E6="Closed Lost","Lost","Open"))) -> Open | X6: =_xlfn.XLOOKUP(B6,'Customers'!A:A,'Customers'!E:E,"") -> Mid-Market | Y6: =IF(OR(W6="Won",W6="Lost"),1,0) -> 0 | Z6: =IF(OR(N6="",P6=""),"",P6-N6) | AA6: =IF(AND(Y6=1,Z6>30),1,0) -> 0
A7: DL-00006 | B7: CUST-0818 | D7: WorkHub Enterprise | E7: Proposal | F7: $73,353 | G7: =IF(F7="","",IF(RIGHT(UPPER(SUBSTITUTE(SUBSTITUTE(SUBSTITUTE(TRIM(F7),"$",""),",","")," ","")),1)="K",VALUE(LEFT(UPPER(SUBSTITUTE(SUBSTITUTE(SUBSTITUTE(TRIM(F7),"$",""),",","")," ","")),LEN(UPPER(SUBSTITUTE(SUBSTITUTE(SUBSTITUTE(TRIM(F7),"$",""),",","")," ","")))-1))*1000,IF(RIGHT(UPPER(SUBSTITUTE(SUBSTITUTE(SUBSTITUTE(TRIM(F7),"$",""),",","")," ","")),1)="M",VALUE(LEFT(UPPER(SUBSTITUTE(SUBSTITUTE(SUBSTITUTE(TRIM(F7),"$",""),",","")," ","")),LEN(UPPER(SUBSTITUTE(SUBSTITUTE(SUBSTITUTE(TRIM(F7),"$",""),",","")," ","")))-1))*1000000,VALUE(SUBSTITUTE(SUBSTITUTE(SUBSTITUTE(TRIM(F7),"$",""),",","")," ",""))))) -> 73353 | H7: LinkedIn Ads | I7: Jairaj Panchal | J7: =PROPER(TRIM(I7)) -> Jairaj Panchal | K7: 2022-11-19 | L7: =IF(K7="","",IF(ISNUMBER(K7),K7,IF(ISNUMBER(SEARCH("/",K7)),DATE(VALUE(RIGHT(K7,4)),VALUE(MID(K7,4,2)),VALUE(LEFT(K7,2))),DATE(VALUE(LEFT(K7,4)),VALUE(MID(K7,6,2)),VALUE(RIGHT(K7,2)))))) -> 44884 | M7: 44917 | N7: =IF(M7="","",IF(ISNUMBER(M7),M7,IF(ISNUMBER(SEARCH("/",M7)),DATE(VALUE(RIGHT(M7,4)),VALUE(MID(M7,4,2)),VALUE(LEFT(M7,2))),DATE(VALUE(LEFT(M7,4)),VALUE(MID(M7,6,2)),VALUE(RIGHT(M7,2)))))) -> 44917 | P7: =IF(O7="","",IF(ISNUMBER(O7),O7,DATE(VALUE(LEFT(O7,4)),VALUE(MID(O7,6,2)),VALUE(RIGHT(O7,2))))) | R7: 0 | S7: 1 | T7: 30.3 | U7: Southeast Asia | V7: 73353 | W7: =IF(E7="","",IF(E7="Closed Won","Won",IF(E7="Closed Lost","Lost","Open"))) -> Open | X7: =_xlfn.XLOOKUP(B7,'Customers'!A:A,'Customers'!E:E,"") -> Enterprise | Y7: =IF(OR(W7="Won",W7="Lost"),1,0) -> 0 | Z7: =IF(OR(N7="",P7=""),"",P7-N7) | AA7: =IF(AND(Y7=1,Z7>30),1,0) -> 0
A8: DL-00007 | B8: CUST-0647 | D8: API Access | E8: Demo | F8: 7K | G8: =IF(F8="","",IF(RIGHT(UPPER(SUBSTITUTE(SUBSTITUTE(SUBSTITUTE(TRIM(F8),"$",""),",","")," ","")),1)="K",VALUE(LEFT(UPPER(SUBSTITUTE(SUBSTITUTE(SUBSTITUTE(TRIM(F8),"$",""),",","")," ","")),LEN(UPPER(SUBSTITUTE(SUBSTITUTE(SUBSTITUTE(TRIM(F8),"$",""),",","")," ","")))-1))*1000,IF(RIGHT(UPPER(SUBSTITUTE(SUBSTITUTE(SUBSTITUTE(TRIM(F8),"$",""),",","")," ","")),1)="M",VALUE(LEFT(UPPER(SUBSTITUTE(SUBSTITUTE(SUBSTITUTE(TRIM(F8),"$",""),",","")," ","")),LEN(UPPER(SUBSTITUTE(SUBSTITUTE(SUBSTITUTE(TRIM(F8),"$",""),",","")," ","")))-1))*1000000,VALUE(SUBSTITUTE(SUBSTITUTE(SUBSTITUTE(TRIM(F8),"$",""),",","")," ",""))))) -> 7000 | H8: Product-Led Signup | I8: Anamika Keer | J8: =PROPER(TRIM(I8)) -> Anamika Keer | K8: 2024-04-16 | L8: =IF(K8="","",IF(ISNUMBER(K8),K8,IF(ISNUMBER(SEARCH("/",K8)),DATE(VALUE(RIGHT(K8,4)),VALUE(MID(K8,4,2)),VALUE(LEFT(K8,2))),DATE(VALUE(LEFT(K8,4)),VALUE(MID(K8,6,2)),VALUE(RIGHT(K8,2)))))) -> 45398 | M8: 45488 | N8: =IF(M8="","",IF(ISNUMBER(M8),M8,IF(ISNUMBER(SEARCH("/",M8)),DATE(VALUE(RIGHT(M8,4)),VALUE(MID(M8,4,2)),VALUE(LEFT(M8,2))),DATE(VALUE(LEFT(M8,4)),VALUE(MID(M8,6,2)),VALUE(RIGHT(M8,2)))))) -> 45488 | P8: =IF(O8="","",IF(ISNUMBER(O8),O8,DATE(VALUE(LEFT(O8,4)),VALUE(MID(O8,6,2)),VALUE(RIGHT(O8,2))))) | R8: 0 | S8: 1 | U8: Middle East | V8: 7000 | W8: =IF(E8="","",IF(E8="Closed Won","Won",IF(E8="Closed Lost","Lost","Open"))) -> Open | X8: =_xlfn.XLOOKUP(B8,'Customers'!A:A,'Customers'!E:E,"") -> SMB | Y8: =IF(OR(W8="Won",W8="Lost"),1,0) -> 0 | Z8: =IF(OR(N8="",P8=""),"",P8-N8) | AA8: =IF(AND(Y8=1,Z8>30),1,0) -> 0
A9: DL-00008 | B9: CUST-0056 | D9: API Access | E9: Demo | F9: 4K | G9: =IF(F9="","",IF(RIGHT(UPPER(SUBSTITUTE(SUBSTITUTE(SUBSTITUTE(TRIM(F9),"$",""),",","")," ","")),1)="K",VALUE(LEFT(UPPER(SUBSTITUTE(SUBSTITUTE(SUBSTITUTE(TRIM(F9),"$",""),",","")," ","")),LEN(UPPER(SUBSTITUTE(SUBSTITUTE(SUBSTITUTE(TRIM(F9),"$",""),",","")," ","")))-1))*1000,IF(RIGHT(UPPER(SUBSTITUTE(SUBSTITUTE(SUBSTITUTE(TRIM(F9),"$",""),",","")," ","")),1)="M",VALUE(LEFT(UPPER(SUBSTITUTE(SUBSTITUTE(SUBSTITUTE(TRIM(F9),"$",""),",","")," ","")),LEN(UPPER(SUBSTITUTE(SUBSTITUTE(SUBSTITUTE(TRIM(F9),"$",""),",","")," ","")))-1))*1000000,VALUE(SUBSTITUTE(SUBSTITUTE(SUBSTITUTE(TRIM(F9),"$",""),",","")," ",""))))) -> 4000 | H9: Webinar | I9: Karan Karnik | J9: =PROPER(TRIM(I9)) -> Karan Karnik | K9: 24/03/2022 | L9: =IF(K9="","",IF(ISNUMBER(K9),K9,IF(ISNUMBER(SEARCH("/",K9)),DATE(VALUE(RIGHT(K9,4)),VALUE(MID(K9,4,2)),VALUE(LEFT(K9,2))),DATE(VALUE(LEFT(K9,4)),VALUE(MID(K9,6,2)),VALUE(RIGHT(K9,2)))))) -> 44644 | M9: 44716 | N9: =IF(M9="","",IF(ISNUMBER(M9),M9,IF(ISNUMBER(SEARCH("/",M9)),DATE(VALUE(RIGHT(M9,4)),VALUE(MID(M9,4,2)),VALUE(LEFT(M9,2))),DATE(VALUE(LEFT(M9,4)),VALUE(MID(M9,6,2)),VALUE(RIGHT(M9,2)))))) -> 44716 | P9: =IF(O9="","",IF(ISNUMBER(O9),O9,DATE(VALUE(LEFT(O9,4)),VALUE(MID(O9,6,2)),VALUE(RIGHT(O9,2))))) | R9: 0 | S9: 1 | T9: 5.5 | U9: Southeast Asia | V9: 4000 | W9: =IF(E9="","",IF(E9="Closed Won","Won",IF(E9="Closed Lost","Lost","Open"))) -> Open | X9: =_xlfn.XLOOKUP(B9,'Customers'!A:A,'Customers'!E:E,"") -> Mid-Market | Y9: =IF(OR(W9="Won",W9="Lost"),1,0) -> 0 | Z9: =IF(OR(N9="",P9=""),"",P9-N9) | AA9: =IF(AND(Y9=1,Z9>30),1,0) -> 0
A10: DL-00009 | B10: CUST-0355 | C10: CMP-054 | D10: WorkHub Core | E10: Demo | F10: 8,506 | G10: =IF(F10="","",IF(RIGHT(UPPER(SUBSTITUTE(SUBSTITUTE(SUBSTITUTE(TRIM(F10),"$",""),",","")," ","")),1)="K",VALUE(LEFT(UPPER(SUBSTITUTE(SUBSTITUTE(SUBSTITUTE(TRIM(F10),"$",""),",","")," ","")),LEN(UPPER(SUBSTITUTE(SUBSTITUTE(SUBSTITUTE(TRIM(F10),"$",""),",","")," ","")))-1))*1000,IF(RIGHT(UPPER(SUBSTITUTE(SUBSTITUTE(SUBSTITUTE(TRIM(F10),"$",""),",","")," ","")),1)="M",VALUE(LEFT(UPPER(SUBSTITUTE(SUBSTITUTE(SUBSTITUTE(TRIM(F10),"$",""),",","")," ","")),LEN(UPPER(SUBSTITUTE(SUBSTITUTE(SUBSTITUTE(TRIM(F10),"$",""),",","")," ","")))-1))*1000000,VALUE(SUBSTITUTE(SUBSTITUTE(SUBSTITUTE(TRIM(F10),"$",""),",","")," ",""))))) -> 8506 | H10: Partner Referral | I10: Shivani Natt | J10: =PROPER(TRIM(I10)) -> Shivani Natt | K10: 2022-11-11 | L10: =IF(K10="","",IF(ISNUMBER(K10),K10,IF(ISNUMBER(SEARCH("/",K10)),DATE(VALUE(RIGHT(K10,4)),VALUE(MID(K10,4,2)),VALUE(LEFT(K10,2))),DATE(VALUE(LEFT(K10,4)),VALUE(MID(K10,6,2)),VALUE(RIGHT(K10,2)))))) -> 44876 | M10: 45028 | N10: =IF(M10="","",IF(ISNUMBER(M10),M10,IF(ISNUMBER(SEARCH("/",M10)),DATE(VALUE(RIGHT(M10,4)),VALUE(MID(M10,4,2)),VALUE(LEFT(M10,2))),DATE(VALUE(LEFT(M10,4)),VALUE(MID(M10,6,2)),VALUE(RIGHT(M10,2)))))) -> 45028 | P10: =IF(O10="","",IF(ISNUMBER(O10),O10,DATE(VALUE(LEFT(O10,4)),VALUE(MID(O10,6,2)),VALUE(RIGHT(O10,2))))) | R10: 0 | S10: 1 | T10: 14.1 | U10: South Asia | V10: 8506 | W10: =IF(E10="","",IF(E10="Closed Won","Won",IF(E10="Closed Lost","Lost","Open"))) -> Open | X10: =_xlfn.XLOOKUP(B10,'Customers'!A:A,'Customers'!E:E,"") -> SMB | Y10: =IF(OR(W10="Won",W10="Lost"),1,0) -> 0 | Z10: =IF(OR(N10="",P10=""),"",P10-N10) | AA10: =IF(AND(Y10=1,Z10>30),1,0) -> 0
A11: DL-00010 | B11: CUST-0537 | C11: CMP-327 | D11: API Access | E11: Proposal | F11: $4,469 | G11: =IF(F11="","",IF(RIGHT(UPPER(SUBSTITUTE(SUBSTITUTE(SUBSTITUTE(TRIM(F11),"$",""),",","")," ","")),1)="K",VALUE(LEFT(UPPER(SUBSTITUTE(SUBSTITUTE(SUBSTITUTE(TRIM(F11),"$",""),",","")," ","")),LEN(UPPER(SUBSTITUTE(SUBSTITUTE(SUBSTITUTE(TRIM(F11),"$",""),",","")," ","")))-1))*1000,IF(RIGHT(UPPER(SUBSTITUTE(SUBSTITUTE(SUBSTITUTE(TRIM(F11),"$",""),",","")," ","")),1)="M",VALUE(LEFT(UPPER(SUBSTITUTE(SUBSTITUTE(SUBSTITUTE(TRIM(F11),"$",""),",","")," ","")),LEN(UPPER(SUBSTITUTE(SUBSTITUTE(SUBSTITUTE(TRIM(F11),"$",""),",","")," ","")))-1))*1000000,VALUE(SUBSTITUTE(SUBSTITUTE(SUBSTITUTE(TRIM(F11),"$",""),",","")," ",""))))) -> 4469 | H11: Product-Led Signup | I11: Mason Solanki | J11: =PROPER(TRIM(I11)) -> Mason Solanki | K11: 2022-01-02 | L11: =IF(K11="","",IF(ISNUMBER(K11),K11,IF(ISNUMBER(SEARCH("/",K11)),DATE(VALUE(RIGHT(K11,4)),VALUE(MID(K11,4,2)),VALUE(LEFT(K11,2))),DATE(VALUE(LEFT(K11,4)),VALUE(MID(K11,6,2)),VALUE(RIGHT(K11,2)))))) -> 44563 | M11: 44723 | N11: =IF(M11="","",IF(ISNUMBER(M11),M11,IF(ISNUMBER(SEARCH("/",M11)),DATE(VALUE(RIGHT(M11,4)),VALUE(MID(M11,4,2)),VALUE(LEFT(M11,2))),DATE(VALUE(LEFT(M11,4)),VALUE(MID(M11,6,2)),VALUE(RIGHT(M11,2)))))) -> 44723 | P11: =IF(O11="","",IF(ISNUMBER(O11),O11,DATE(VALUE(LEFT(O11,4)),VALUE(MID(O11,6,2)),VALUE(RIGHT(O11,2))))) | R11: 0 | S11: 1 | T11: 32 | U11: Southeast Asia | V11: 4469 | W11: =IF(E11="","",IF(E11="Closed Won","Won",IF(E11="Closed Lost","Lost","Open"))) -> Open | X11: =_xlfn.XLOOKUP(B11,'Customers'!A:A,'Customers'!E:E,"") -> Enterprise | Y11: =IF(OR(W11="Won",W11="Lost"),1,0) -> 0 | Z11: =IF(OR(N11="",P11=""),"",P11-N11) | AA11: =IF(AND(Y11=1,Z11>30),1,0) -> 0
A12: DL-00011 | B12: CUST-1067 | C12: CMP-224 | D12: WorkHub Enterprise | E12: Closed Won | F12: $178,212 | G12: =IF(F12="","",IF(RIGHT(UPPER(SUBSTITUTE(SUBSTITUTE(SUBSTITUTE(TRIM(F12),"$",""),",","")," ","")),1)="K",VALUE(LEFT(UPPER(SUBSTITUTE(SUBSTITUTE(SUBSTITUTE(TRIM(F12),"$",""),",","")," ","")),LEN(UPPER(SUBSTITUTE(SUBSTITUTE(SUBSTITUTE(TRIM(F12),"$",""),",","")," ","")))-1))*1000,IF(RIGHT(UPPER(SUBSTITUTE(SUBSTITUTE(SUBSTITUTE(TRIM(F12),"$",""),",","")," ","")),1)="M",VALUE(LEFT(UPPER(SUBSTITUTE(SUBSTITUTE(SUBSTITUTE(TRIM(F12),"$",""),",","")," ","")),LEN(UPPER(SUBSTITUTE(SUBSTITUTE(SUBSTITUTE(TRIM(F12),"$",""),",","")," ","")))-1))*1000000,VALUE(SUBSTITUTE(SUBSTITUTE(SUBSTITUTE(TRIM(F12),"$",""),",","")," ",""))))) -> 178212 | H12: Product-Led Signup | I12: Owen Mane | J12: =PROPER(TRIM(I12)) -> Owen Mane | K12: 29/09/2023 | L12: =IF(K12="","",IF(ISNUMBER(K12),K12,IF(ISNUMBER(SEARCH("/",K12)),DATE(VALUE(RIGHT(K12,4)),VALUE(MID(K12,4,2)),VALUE(LEFT(K12,2))),DATE(VALUE(LEFT(K12,4)),VALUE(MID(K12,6,2)),VALUE(RIGHT(K12,2)))))) -> 45198 | M12: 45324 | N12: =IF(M12="","",IF(ISNUMBER(M12),M12,IF(ISNUMBER(SEARCH("/",M12)),DATE(VALUE(RIGHT(M12,4)),VALUE(MID(M12,4,2)),VALUE(LEFT(M12,2))),DATE(VALUE(LEFT(M12,4)),VALUE(MID(M12,6,2)),VALUE(RIGHT(M12,2)))))) -> 45324 | O12: 45273 | P12: =IF(O12="","",IF(ISNUMBER(O12),O12,DATE(VALUE(LEFT(O12,4)),VALUE(MID(O12,6,2)),VALUE(RIGHT(O12,2))))) -> 45273 | Q12: 75 | R12: 1 | S12: 2 | T12: 3.9 | U12: Southeast Asia | V12: 178212 | W12: =IF(E12="","",IF(E12="Closed Won","Won",IF(E12="Closed Lost","Lost","Open"))) -> Won | X12: =_xlfn.XLOOKUP(B12,'Customers'!A:A,'Customers'!E:E,"") -> Mid-Market | Y12: =IF(OR(W12="Won",W12="Lost"),1,0) -> 1 | Z12: =IF(OR(N12="",P12=""),"",P12-N12) -> -51 | AA12: =IF(AND(Y12=1,Z12>30),1,0) -> 0
A13: DL-00012 | B13: CUST-0375 | D13: WorkHub Core | E13: Demo | F13: 3,564 | G13: =IF(F13="","",IF(RIGHT(UPPER(SUBSTITUTE(SUBSTITUTE(SUBSTITUTE(TRIM(F13),"$",""),",","")," ","")),1)="K",VALUE(LEFT(UPPER(SUBSTITUTE(SUBSTITUTE(SUBSTITUTE(TRIM(F13),"$",""),",","")," ","")),LEN(UPPER(SUBSTITUTE(SUBSTITUTE(SUBSTITUTE(TRIM(F13),"$",""),",","")," ","")))-1))*1000,IF(RIGHT(UPPER(SUBSTITUTE(SUBSTITUTE(SUBSTITUTE(TRIM(F13),"$",""),",","")," ","")),1)="M",VALUE(LEFT(UPPER(SUBSTITUTE(SUBSTITUTE(SUBSTITUTE(TRIM(F13),"$",""),",","")," ","")),LEN(UPPER(SUBSTITUTE(SUBSTITUTE(SUBSTITUTE(TRIM(F13),"$",""),",","")," ","")))-1))*1000000,VALUE(SUBSTITUTE(SUBSTITUTE(SUBSTITUTE(TRIM(F13),"$",""),",","")," ",""))))) -> 3564 | H13: Paid Search | I13: Amruta Sinha | J13: =PROPER(TRIM(I13)) -> Amruta Sinha | K13: 2022-08-19 | L13: =IF(K13="","",IF(ISNUMBER(K13),K13,IF(ISNUMBER(SEARCH("/",K13)),DATE(VALUE(RIGHT(K13,4)),VALUE(MID(K13,4,2)),VALUE(LEFT(K13,2))),DATE(VALUE(LEFT(K13,4)),VALUE(MID(K13,6,2)),VALUE(RIGHT(K13,2)))))) -> 44792 | M13: 44937 | N13: =IF(M13="","",IF(ISNUMBER(M13),M13,IF(ISNUMBER(SEARCH("/",M13)),DATE(VALUE(RIGHT(M13,4)),VALUE(MID(M13,4,2)),VALUE(LEFT(M13,2))),DATE(VALUE(LEFT(M13,4)),VALUE(MID(M13,6,2)),VALUE(RIGHT(M13,2)))))) -> 44937 | P13: =IF(O13="","",IF(ISNUMBER(O13),O13,DATE(VALUE(LEFT(O13,4)),VALUE(MID(O13,6,2)),VALUE(RIGHT(O13,2))))) | R13: 0 | S13: 1 | T13: 19.9 | U13: East Africa | V13: 3564 | W13: =IF(E13="","",IF(E13="Closed Won","Won",IF(E13="Closed Lost","Lost","Open"))) -> Open | X13: =_xlfn.XLOOKUP(B13,'Customers'!A:A,'Customers'!E:E,"") -> Mid-Market | Y13: =IF(OR(W13="Won",W13="Lost"),1,0) -> 0 | Z13: =IF(OR(N13="",P13=""),"",P13-N13) | AA13: =IF(AND(Y13=1,Z13>30),1,0) -> 0
A14: DL-00013 | B14: CUST-0833 | C14: CMP-378 | D14: API Access | E14: Negotiation | F14: 5,862 | G14: =IF(F14="","",IF(RIGHT(UPPER(SUBSTITUTE(SUBSTITUTE(SUBSTITUTE(TRIM(F14),"$",""),",","")," ","")),1)="K",VALUE(LEFT(UPPER(SUBSTITUTE(SUBSTITUTE(SUBSTITUTE(TRIM(F14),"$",""),",","")," ","")),LEN(UPPER(SUBSTITUTE(SUBSTITUTE(SUBSTITUTE(TRIM(F14),"$",""),",","")," ","")))-1))*1000,IF(RIGHT(UPPER(SUBSTITUTE(SUBSTITUTE(SUBSTITUTE(TRIM(F14),"$",""),",","")," ","")),1)="M",VALUE(LEFT(UPPER(SUBSTITUTE(SUBSTITUTE(SUBSTITUTE(TRIM(F14),"$",""),",","")," ","")),LEN(UPPER(SUBSTITUTE(SUBSTITUTE(SUBSTITUTE(TRIM(F14),"$",""),",","")," ","")))-1))*1000000,VALUE(SUBSTITUTE(SUBSTITUTE(SUBSTITUTE(TRIM(F14),"$",""),",","")," ",""))))) -> 5862 | H14: Partner Referral | I14: Hemangini Bahri | J14: =PROPER(TRIM(I14)) -> Hemangini Bahri | K14: 2023-02-12 | L14: =IF(K14="","",IF(ISNUMBER(K14),K14,IF(ISNUMBER(SEARCH("/",K14)),DATE(VALUE(RIGHT(K14,4)),VALUE(MID(K14,4,2)),VALUE(LEFT(K14,2))),DATE(VALUE(LEFT(K14,4)),VALUE(MID(K14,6,2)),VALUE(RIGHT(K14,2)))))) -> 44969 | M14: 44998 | N14: =IF(M14="","",IF(ISNUMBER(M14),M14,IF(ISNUMBER(SEARCH("/",M14)),DATE(VALUE(RIGHT(M14,4)),VALUE(MID(M14,4,2)),VALUE(LEFT(M14,2))),DATE(VALUE(LEFT(M14,4)),VALUE(MID(M14,6,2)),VALUE(RIGHT(M14,2)))))) -> 44998 | P14: =IF(O14="","",IF(ISNUMBER(O14),O14,DATE(VALUE(LEFT(O14,4)),VALUE(MID(O14,6,2)),VALUE(RIGHT(O14,2))))) | R14: 0 | S14: 1 | T14: 15.1 | U14: Southeast Asia | V14: 5862 | W14: =IF(E14="","",IF(E14="Closed Won","Won",IF(E14="Closed Lost","Lost","Open"))) -> Open | X14: =_xlfn.XLOOKUP(B14,'Customers'!A:A,'Customers'!E:E,"") -> Mid-Market | Y14: =IF(OR(W14="Won",W14="Lost"),1,0) -> 0 | Z14: =IF(OR(N14="",P14=""),"",P14-N14) | AA14: =IF(AND(Y14=1,Z14>30),1,0) -> 0
A15: DL-00014 | B15: CUST-0128 | C15: CMP-121 | D15: WorkHub Core | E15: Demo | F15: 1K | G15: =IF(F15="","",IF(RIGHT(UPPER(SUBSTITUTE(SUBSTITUTE(SUBSTITUTE(TRIM(F15),"$",""),",","")," ","")),1)="K",VALUE(LEFT(UPPER(SUBSTITUTE(SUBSTITUTE(SUBSTITUTE(TRIM(F15),"$",""),",","")," ","")),LEN(UPPER(SUBSTITUTE(SUBSTITUTE(SUBSTITUTE(TRIM(F15),"$",""),",","")," ","")))-1))*1000,IF(RIGHT(UPPER(SUBSTITUTE(SUBSTITUTE(SUBSTITUTE(TRIM(F15),"$",""),",","")," ","")),1)="M",VALUE(LEFT(UPPER(SUBSTITUTE(SUBSTITUTE(SUBSTITUTE(TRIM(F15),"$",""),",","")," ","")),LEN(UPPER(SUBSTITUTE(SUBSTITUTE(SUBSTITUTE(TRIM(F15),"$",""),",","")," ","")))-1))*1000000,VALUE(SUBSTITUTE(SUBSTITUTE(SUBSTITUTE(TRIM(F15),"$",""),",","")," ",""))))) -> 1000 | H15: Webinar | I15: Ati Seshadri | J15: =PROPER(TRIM(I15)) -> Ati Seshadri | K15: 2022-07-17 | L15: =IF(K15="","",IF(ISNUMBER(K15),K15,IF(ISNUMBER(SEARCH("/",K15)),DATE(VALUE(RIGHT(K15,4)),VALUE(MID(K15,4,2)),VALUE(LEFT(K15,2))),DATE(VALUE(LEFT(K15,4)),VALUE(MID(K15,6,2)),VALUE(RIGHT(K15,2)))))) -> 44759 | M15: 44857 | N15: =IF(M15="","",IF(ISNUMBER(M15),M15,IF(ISNUMBER(SEARCH("/",M15)),DATE(VALUE(RIGHT(M15,4)),VALUE(MID(M15,4,2)),VALUE(LEFT(M15,2))),DATE(VALUE(LEFT(M15,4)),VALUE(MID(M15,6,2)),VALUE(RIGHT(M15,2)))))) -> 44857 | P15: =IF(O15="","",IF(ISNUMBER(O15),O15,DATE(VALUE(LEFT(O15,4)),VALUE(MID(O15,6,2)),VALUE(RIGHT(O15,2))))) | R15: 0 | S15: 1 | T15: 9.5 | U15: South Asia | V15: 1000 | W15: =IF(E15="","",IF(E15="Closed Won","Won",IF(E15="Closed Lost","Lost","Open"))) -> Open | X15: =_xlfn.XLOOKUP(B15,'Customers'!A:A,'Customers'!E:E,"") -> SMB | Y15: =IF(OR(W15="Won",W15="Lost"),1,0) -> 0 | Z15: =IF(OR(N15="",P15=""),"",P15-N15) | AA15: =IF(AND(Y15=1,Z15>30),1,0) -> 0
A16: DL-00015 | B16: CUST-1133 | C16: CMP-091 | D16: WorkHub Pro | E16: Closed Lost | F16: 24887 | G16: =IF(F16="","",IF(RIGHT(UPPER(SUBSTITUTE(SUBSTITUTE(SUBSTITUTE(TRIM(F16),"$",""),",","")," ","")),1)="K",VALUE(LEFT(UPPER(SUBSTITUTE(SUBSTITUTE(SUBSTITUTE(TRIM(F16),"$",""),",","")," ","")),LEN(UPPER(SUBSTITUTE(SUBSTITUTE(SUBSTITUTE(TRIM(F16),"$",""),",","")," ","")))-1))*1000,IF(RIGHT(UPPER(SUBSTITUTE(SUBSTITUTE(SUBSTITUTE(TRIM(F16),"$",""),",","")," ","")),1)="M",VALUE(LEFT(UPPER(SUBSTITUTE(SUBSTITUTE(SUBSTITUTE(TRIM(F16),"$",""),",","")," ","")),LEN(UPPER(SUBSTITUTE(SUBSTITUTE(SUBSTITUTE(TRIM(F16),"$",""),",","")," ","")))-1))*1000000,VALUE(SUBSTITUTE(SUBSTITUTE(SUBSTITUTE(TRIM(F16),"$",""),",","")," ",""))))) -> 24887 | H16: LinkedIn Ads | I16: Ekta Uppal | J16: =PROPER(TRIM(I16)) -> Ekta Uppal | K16: 2024-07-12 | L16: =IF(K16="","",IF(ISNUMBER(K16),K16,IF(ISNUMBER(SEARCH("/",K16)),DATE(VALUE(RIGHT(K16,4)),VALUE(MID(K16,4,2)),VALUE(LEFT(K16,2))),DATE(VALUE(LEFT(K16,4)),VALUE(MID(K16,6,2)),VALUE(RIGHT(K16,2)))))) -> 45485 | M16: 45541 | N16: =IF(M16="","",IF(ISNUMBER(M16),M16,IF(ISNUMBER(SEARCH("/",M16)),DATE(VALUE(RIGHT(M16,4)),VALUE(MID(M16,4,2)),VALUE(LEFT(M16,2))),DATE(VALUE(LEFT(M16,4)),VALUE(MID(M16,6,2)),VALUE(RIGHT(M16,2)))))) -> 45541 | O16: 45616 | P16: =IF(O16="","",IF(ISNUMBER(O16),O16,DATE(VALUE(LEFT(O16,4)),VALUE(MID(O16,6,2)),VALUE(RIGHT(O16,2))))) -> 45616 | Q16: 131 | R16: 0 | S16: 1 | T16: 32.7 | U16: Southeast Asia | V16: 24887 | W16: =IF(E16="","",IF(E16="Closed Won","Won",IF(E16="Closed Lost","Lost","Open"))) -> Lost | X16: =_xlfn.XLOOKUP(B16,'Customers'!A:A,'Customers'!E:E,"") -> Mid-Market | Y16: =IF(OR(W16="Won",W16="Lost"),1,0) -> 1 | Z16: =IF(OR(N16="",P16=""),"",P16-N16) -> 75 | AA16: =IF(AND(Y16=1,Z16>30),1,0) -> 1
A17: DL-00016 | B17: CUST-1028 | C17: CMP-127 | D17: API Access | E17: Closed Lost | F17: $10,459 | G17: =IF(F17="","",IF(RIGHT(UPPER(SUBSTITUTE(SUBSTITUTE(SUBSTITUTE(TRIM(F17),"$",""),",","")," ","")),1)="K",VALUE(LEFT(UPPER(SUBSTITUTE(SUBSTITUTE(SUBSTITUTE(TRIM(F17),"$",""),",","")," ","")),LEN(UPPER(SUBSTITUTE(SUBSTITUTE(SUBSTITUTE(TRIM(F17),"$",""),",","")," ","")))-1))*1000,IF(RIGHT(UPPER(SUBSTITUTE(SUBSTITUTE(SUBSTITUTE(TRIM(F17),"$",""),",","")," ","")),1)="M",VALUE(LEFT(UPPER(SUBSTITUTE(SUBSTITUTE(SUBSTITUTE(TRIM(F17),"$",""),",","")," ","")),LEN(UPPER(SUBSTITUTE(SUBSTITUTE(SUBSTITUTE(TRIM(F17),"$",""),",","")," ","")))-1))*1000000,VALUE(SUBSTITUTE(SUBSTITUTE(SUBSTITUTE(TRIM(F17),"$",""),",","")," ",""))))) -> 10459 | H17: Webinar | I17: Karan Karnik | J17: =PROPER(TRIM(I17)) -> Karan Karnik | K17: 2024-11-01 | L17: =IF(K17="","",IF(ISNUMBER(K17),K17,IF(ISNUMBER(SEARCH("/",K17)),DATE(VALUE(RIGHT(K17,4)),VALUE(MID(K17,4,2)),VALUE(LEFT(K17,2))),DATE(VALUE(LEFT(K17,4)),VALUE(MID(K17,6,2)),VALUE(RIGHT(K17,2)))))) -> 45597 | M17: 45773 | N17: =IF(M17="","",IF(ISNUMBER(M17),M17,IF(ISNUMBER(SEARCH("/",M17)),DATE(VALUE(RIGHT(M17,4)),VALUE(MID(M17,4,2)),VALUE(LEFT(M17,2))),DATE(VALUE(LEFT(M17,4)),VALUE(MID(M17,6,2)),VALUE(RIGHT(M17,2)))))) -> 45773 | O17: 45720 | P17: =IF(O17="","",IF(ISNUMBER(O17),O17,DATE(VALUE(LEFT(O17,4)),VALUE(MID(O17,6,2)),VALUE(RIGHT(O17,2))))) -> 45720 | Q17: 123 | R17: 0 | S17: 1 | T17: 6.2 | U17: Middle East | V17: 10459 | W17: =IF(E17="","",IF(E17="Closed Won","Won",IF(E17="Closed Lost","Lost","Open"))) -> Lost | X17: =_xlfn.XLOOKUP(B17,'Customers'!A:A,'Customers'!E:E,"") -> SMB | Y17: =IF(OR(W17="Won",W17="Lost"),1,0) -> 1 | Z17: =IF(OR(N17="",P17=""),"",P17-N17) -> -53 | AA17: =IF(AND(Y17=1,Z17>30),1,0) -> 0
A18: DL-00017 | B18: CUST-0223 | C18: CMP-378 | D18: WorkHub Core | E18: Closed Lost | F18: $7,222 | G18: =IF(F18="","",IF(RIGHT(UPPER(SUBSTITUTE(SUBSTITUTE(SUBSTITUTE(TRIM(F18),"$",""),",","")," ","")),1)="K",VALUE(LEFT(UPPER(SUBSTITUTE(SUBSTITUTE(SUBSTITUTE(TRIM(F18),"$",""),",","")," ","")),LEN(UPPER(SUBSTITUTE(SUBSTITUTE(SUBSTITUTE(TRIM(F18),"$",""),",","")," ","")))-1))*1000,IF(RIGHT(UPPER(SUBSTITUTE(SUBSTITUTE(SUBSTITUTE(TRIM(F18),"$",""),",","")," ","")),1)="M",VALUE(LEFT(UPPER(SUBSTITUTE(SUBSTITUTE(SUBSTITUTE(TRIM(F18),"$",""),",","")," ","")),LEN(UPPER(SUBSTITUTE(SUBSTITUTE(SUBSTITUTE(TRIM(F18),"$",""),",","")," ","")))-1))*1000000,VALUE(SUBSTITUTE(SUBSTITUTE(SUBSTITUTE(TRIM(F18),"$",""),",","")," ",""))))) -> 7222 | H18: Webinar | I18: Kashish Patla | J18: =PROPER(TRIM(I18)) -> Kashish Patla | K18: 2023-04-08 | L18: =IF(K18="","",IF(ISNUMBER(K18),K18,IF(ISNUMBER(SEARCH("/",K18)),DATE(VALUE(RIGHT(K18,4)),VALUE(MID(K18,4,2)),VALUE(LEFT(K18,2))),DATE(VALUE(LEFT(K18,4)),VALUE(MID(K18,6,2)),VALUE(RIGHT(K18,2)))))) -> 45024 | M18: 45177 | N18: =IF(M18="","",IF(ISNUMBER(M18),M18,IF(ISNUMBER(SEARCH("/",M18)),DATE(VALUE(RIGHT(M18,4)),VALUE(MID(M18,4,2)),VALUE(LEFT(M18,2))),DATE(VALUE(LEFT(M18,4)),VALUE(MID(M18,6,2)),VALUE(RIGHT(M18,2)))))) -> 45177 | O18: 45101 | P18: =IF(O18="","",IF(ISNUMBER(O18),O18,DATE(VALUE(LEFT(O18,4)),VALUE(MID(O18,6,2)),VALUE(RIGHT(O18,2))))) -> 45101 | Q18: 77 | R18: 0 | S18: 1 | T18: 12.2 | U18: South Asia | V18: 7222 | W18: =IF(E18="","",IF(E18="Closed Won","Won",IF(E18="Closed Lost","Lost","Open"))) -> Lost | X18: =_xlfn.XLOOKUP(B18,'Customers'!A:A,'Customers'!E:E,"") -> Mid-Market | Y18: =IF(OR(W18="Won",W18="Lost"),1,0) -> 1 | Z18: =IF(OR(N18="",P18=""),"",P18-N18) -> -76 | AA18: =IF(AND(Y18=1,Z18>30),1,0) -> 0
A19: DL-00018 | B19: CUST-0667 | C19: CMP-335 | D19: WorkHub Core | E19: Demo | F19: $8,134 | G19: =IF(F19="","",IF(RIGHT(UPPER(SUBSTITUTE(SUBSTITUTE(SUBSTITUTE(TRIM(F19),"$",""),",","")," ","")),1)="K",VALUE(LEFT(UPPER(SUBSTITUTE(SUBSTITUTE(SUBSTITUTE(TRIM(F19),"$",""),",","")," ","")),LEN(UPPER(SUBSTITUTE(SUBSTITUTE(SUBSTITUTE(TRIM(F19),"$",""),",","")," ","")))-1))*1000,IF(RIGHT(UPPER(SUBSTITUTE(SUBSTITUTE(SUBSTITUTE(TRIM(F19),"$",""),",","")," ","")),1)="M",VALUE(LEFT(UPPER(SUBSTITUTE(SUBSTITUTE(SUBSTITUTE(TRIM(F19),"$",""),",","")," ","")),LEN(UPPER(SUBSTITUTE(SUBSTITUTE(SUBSTITUTE(TRIM(F19),"$",""),",","")," ","")))-1))*1000000,VALUE(SUBSTITUTE(SUBSTITUTE(SUBSTITUTE(TRIM(F19),"$",""),",","")," ",""))))) -> 8134 | H19: Event | I19: Aachal Soni | J19: =PROPER(TRIM(I19)) -> Aachal Soni | K19: 2024-01-29 | L19: =IF(K19="","",IF(ISNUMBER(K19),K19,IF(ISNUMBER(SEARCH("/",K19)),DATE(VALUE(RIGHT(K19,4)),VALUE(MID(K19,4,2)),VALUE(LEFT(K19,2))),DATE(VALUE(LEFT(K19,4)),VALUE(MID(K19,6,2)),VALUE(RIGHT(K19,2)))))) -> 45320 | M19: 45497 | N19: =IF(M19="","",IF(ISNUMBER(M19),M19,IF(ISNUMBER(SEARCH("/",M19)),DATE(VALUE(RIGHT(M19,4)),VALUE(MID(M19,4,2)),VALUE(LEFT(M19,2))),DATE(VALUE(LEFT(M19,4)),VALUE(MID(M19,6,2)),VALUE(RIGHT(M19,2)))))) -> 45497 | P19: =IF(O19="","",IF(ISNUMBER(O19),O19,DATE(VALUE(LEFT(O19,4)),VALUE(MID(O19,6,2)),VALUE(RIGHT(O19,2))))) | R19: 0 | S19: 1 | U19: Southeast Asia | V19: 8134 | W19: =IF(E19="","",IF(E19="Closed Won","Won",IF(E19="Closed Lost","Lost","Open"))) -> Open | X19: =_xlfn.XLOOKUP(B19,'Customers'!A:A,'Customers'!E:E,"") -> SMB | Y19: =IF(OR(W19="Won",W19="Lost"),1,0) -> 0 | Z19: =IF(OR(N19="",P19=""),"",P19-N19) | AA19: =IF(AND(Y19=1,Z19>30),1,0) -> 0
A20: DL-00019 | B20: CUST-1273 | C20: CMP-339 | D20: WorkHub Pro | E20: Proposal | F20: 46,846 | G20: =IF(F20="","",IF(RIGHT(UPPER(SUBSTITUTE(SUBSTITUTE(SUBSTITUTE(TRIM(F20),"$",""),",","")," ","")),1)="K",VALUE(LEFT(UPPER(SUBSTITUTE(SUBSTITUTE(SUBSTITUTE(TRIM(F20),"$",""),",","")," ","")),LEN(UPPER(SUBSTITUTE(SUBSTITUTE(SUBSTITUTE(TRIM(F20),"$",""),",","")," ","")))-1))*1000,IF(RIGHT(UPPER(SUBSTITUTE(SUBSTITUTE(SUBSTITUTE(TRIM(F20),"$",""),",","")," ","")),1)="M",VALUE(LEFT(UPPER(SUBSTITUTE(SUBSTITUTE(SUBSTITUTE(TRIM(F20),"$",""),",","")," ","")),LEN(UPPER(SUBSTITUTE(SUBSTITUTE(SUBSTITUTE(TRIM(F20),"$",""),",","")," ","")))-1))*1000000,VALUE(SUBSTITUTE(SUBSTITUTE(SUBSTITUTE(TRIM(F20),"$",""),",","")," ",""))))) -> 46846 | H20: Event | I20: Champak Rao | J20: =PROPER(TRIM(I20)) -> Champak Rao | K20: 2023-12-23 | L20: =IF(K20="","",IF(ISNUMBER(K20),K20,IF(ISNUMBER(SEARCH("/",K20)),DATE(VALUE(RIGHT(K20,4)),VALUE(MID(K20,4,2)),VALUE(LEFT(K20,2))),DATE(VALUE(LEFT(K20,4)),VALUE(MID(K20,6,2)),VALUE(RIGHT(K20,2)))))) -> 45283 | M20: 45434 | N20: =IF(M20="","",IF(ISNUMBER(M20),M20,IF(ISNUMBER(SEARCH("/",M20)),DATE(VALUE(RIGHT(M20,4)),VALUE(MID(M20,4,2)),VALUE(LEFT(M20,2))),DATE(VALUE(LEFT(M20,4)),VALUE(MID(M20,6,2)),VALUE(RIGHT(M20,2)))))) -> 45434 | P20: =IF(O20="","",IF(ISNUMBER(O20),O20,DATE(VALUE(LEFT(O20,4)),VALUE(MID(O20,6,2)),VALUE(RIGHT(O20,2))))) | R20: 0 | S20: 1 | T20: 18.9 | U20: South Asia | V20: 46846 | W20: =IF(E20="","",IF(E20="Closed Won","Won",IF(E20="Closed Lost","Lost","Open"))) -> Open | X20: =_xlfn.XLOOKUP(B20,'Customers'!A:A,'Customers'!E:E,"") -> Enterprise | Y20: =IF(OR(W20="Won",W20="Lost"),1,0) -> 0 | Z20: =IF(OR(N20="",P20=""),"",P20-N20) | AA20: =IF(AND(Y20=1,Z20>30),1,0) -> 0
A21: DL-00020 | B21: CUST-1499 | C21: CMP-140 | D21: WorkHub Pro | E21: Closed Won | F21: $33,087 | G21: =IF(F21="","",IF(RIGHT(UPPER(SUBSTITUTE(SUBSTITUTE(SUBSTITUTE(TRIM(F21),"$",""),",","")," ","")),1)="K",VALUE(LEFT(UPPER(SUBSTITUTE(SUBSTITUTE(SUBSTITUTE(TRIM(F21),"$",""),",","")," ","")),LEN(UPPER(SUBSTITUTE(SUBSTITUTE(SUBSTITUTE(TRIM(F21),"$",""),",","")," ","")))-1))*1000,IF(RIGHT(UPPER(SUBSTITUTE(SUBSTITUTE(SUBSTITUTE(TRIM(F21),"$",""),",","")," ","")),1)="M",VALUE(LEFT(UPPER(SUBSTITUTE(SUBSTITUTE(SUBSTITUTE(TRIM(F21),"$",""),",","")," ","")),LEN(UPPER(SUBSTITUTE(SUBSTITUTE(SUBSTITUTE(TRIM(F21),"$",""),",","")," ","")))-1))*1000000,VALUE(SUBSTITUTE(SUBSTITUTE(SUBSTITUTE(TRIM(F21),"$",""),",","")," ",""))))) -> 33087 | H21: Product-Led Signup | I21: Krish Varughese | J21: =PROPER(TRIM(I21)) -> Krish Varughese | K21: 2022-12-16 | L21: =IF(K21="","",IF(ISNUMBER(K21),K21,IF(ISNUMBER(SEARCH("/",K21)),DATE(VALUE(RIGHT(K21,4)),VALUE(MID(K21,4,2)),VALUE(LEFT(K21,2))),DATE(VALUE(LEFT(K21,4)),VALUE(MID(K21,6,2)),VALUE(RIGHT(K21,2)))))) -> 44911 | M21: 44950 | N21: =IF(M21="","",IF(ISNUMBER(M21),M21,IF(ISNUMBER(SEARCH("/",M21)),DATE(VALUE(RIGHT(M21,4)),VALUE(MID(M21,4,2)),VALUE(LEFT(M21,2))),DATE(VALUE(LEFT(M21,4)),VALUE(MID(M21,6,2)),VALUE(RIGHT(M21,2)))))) -> 44950 | O21: 45045 | P21: =IF(O21="","",IF(ISNUMBER(O21),O21,DATE(VALUE(LEFT(O21,4)),VALUE(MID(O21,6,2)),VALUE(RIGHT(O21,2))))) -> 45045 | Q21: 134 | R21: 1 | S21: 2 | T21: 12 | U21: South Asia | V21: 33087 | W21: =IF(E21="","",IF(E21="Closed Won","Won",IF(E21="Closed Lost","Lost","Open"))) -> Won | X21: =_xlfn.XLOOKUP(B21,'Customers'!A:A,'Customers'!E:E,"") -> Mid-Market | Y21: =IF(OR(W21="Won",W21="Lost"),1,0) -> 1 | Z21: =IF(OR(N21="",P21=""),"",P21-N21) -> 95 | AA21: =IF(AND(Y21=1,Z21>30),1,0) -> 1
A22: DL-00021 | B22: CUST-1485 | C22: CMP-012 | D22: WorkHub Enterprise | E22: Closed Lost | F22: 119072 | G22: =IF(F22="","",IF(RIGHT(UPPER(SUBSTITUTE(SUBSTITUTE(SUBSTITUTE(TRIM(F22),"$",""),",","")," ","")),1)="K",VALUE(LEFT(UPPER(SUBSTITUTE(SUBSTITUTE(SUBSTITUTE(TRIM(F22),"$",""),",","")," ","")),LEN(UPPER(SUBSTITUTE(SUBSTITUTE(SUBSTITUTE(TRIM(F22),"$",""),",","")," ","")))-1))*1000,IF(RIGHT(UPPER(SUBSTITUTE(SUBSTITUTE(SUBSTITUTE(TRIM(F22),"$",""),",","")," ","")),1)="M",VALUE(LEFT(UPPER(SUBSTITUTE(SUBSTITUTE(SUBSTITUTE(TRIM(F22),"$",""),",","")," ","")),LEN(UPPER(SUBSTITUTE(SUBSTITUTE(SUBSTITUTE(TRIM(F22),"$",""),",","")," ","")))-1))*1000000,VALUE(SUBSTITUTE(SUBSTITUTE(SUBSTITUTE(TRIM(F22),"$",""),",","")," ",""))))) -> 119072 | H22: Inbound Organic | I22: Nihal Bhasin | J22: =PROPER(TRIM(I22)) -> Nihal Bhasin | K22: 2024-04-23 | L22: =IF(K22="","",IF(ISNUMBER(K22),K22,IF(ISNUMBER(SEARCH("/",K22)),DATE(VALUE(RIGHT(K22,4)),VALUE(MID(K22,4,2)),VALUE(LEFT(K22,2))),DATE(VALUE(LEFT(K22,4)),VALUE(MID(K22,6,2)),VALUE(RIGHT(K22,2)))))) -> 45405 | M22: 45497 | N22: =IF(M22="","",IF(ISNUMBER(M22),M22,IF(ISNUMBER(SEARCH("/",M22)),DATE(VALUE(RIGHT(M22,4)),VALUE(MID(M22,4,2)),VALUE(LEFT(M22,2))),DATE(VALUE(LEFT(M22,4)),VALUE(MID(M22,6,2)),VALUE(RIGHT(M22,2)))))) -> 45497 | O22: 45537 | P22: =IF(O22="","",IF(ISNUMBER(O22),O22,DATE(VALUE(LEFT(O22,4)),VALUE(MID(O22,6,2)),VALUE(RIGHT(O22,2))))) -> 45537 | Q22: 132 | R22: 0 | S22: 1 | T22: 20.1 | U22: East Africa | V22: 119072 | W22: =IF(E22="","",IF(E22="Closed Won","Won",IF(E22="Closed Lost","Lost","Open"))) -> Lost | X22: =_xlfn.XLOOKUP(B22,'Customers'!A:A,'Customers'!E:E,"") -> Mid-Market | Y22: =IF(OR(W22="Won",W22="Lost"),1,0) -> 1 | Z22: =IF(OR(N22="",P22=""),"",P22-N22) -> 40 | AA22: =IF(AND(Y22=1,Z22>30),1,0) -> 1
A23: DL-00022 | B23: CUST-0937 | D23: WorkHub Enterprise | E23: Negotiation | F23: $116,146 | G23: =IF(F23="","",IF(RIGHT(UPPER(SUBSTITUTE(SUBSTITUTE(SUBSTITUTE(TRIM(F23),"$",""),",","")," ","")),1)="K",VALUE(LEFT(UPPER(SUBSTITUTE(SUBSTITUTE(SUBSTITUTE(TRIM(F23),"$",""),",","")," ","")),LEN(UPPER(SUBSTITUTE(SUBSTITUTE(SUBSTITUTE(TRIM(F23),"$",""),",","")," ","")))-1))*1000,IF(RIGHT(UPPER(SUBSTITUTE(SUBSTITUTE(SUBSTITUTE(TRIM(F23),"$",""),",","")," ","")),1)="M",VALUE(LEFT(UPPER(SUBSTITUTE(SUBSTITUTE(SUBSTITUTE(TRIM(F23),"$",""),",","")," ","")),LEN(UPPER(SUBSTITUTE(SUBSTITUTE(SUBSTITUTE(TRIM(F23),"$",""),",","")," ","")))-1))*1000000,VALUE(SUBSTITUTE(SUBSTITUTE(SUBSTITUTE(TRIM(F23),"$",""),",","")," ",""))))) -> 116146 | H23: Event | I23: Lakshmi Hayre | J23: =PROPER(TRIM(I23)) -> Lakshmi Hayre | K23: 2023-08-06 | L23: =IF(K23="","",IF(ISNUMBER(K23),K23,IF(ISNUMBER(SEARCH("/",K23)),DATE(VALUE(RIGHT(K23,4)),VALUE(MID(K23,4,2)),VALUE(LEFT(K23,2))),DATE(VALUE(LEFT(K23,4)),VALUE(MID(K23,6,2)),VALUE(RIGHT(K23,2)))))) -> 45144 | M23: 45289 | N23: =IF(M23="","",IF(ISNUMBER(M23),M23,IF(ISNUMBER(SEARCH("/",M23)),DATE(VALUE(RIGHT(M23,4)),VALUE(MID(M23,4,2)),VALUE(LEFT(M23,2))),DATE(VALUE(LEFT(M23,4)),VALUE(MID(M23,6,2)),VALUE(RIGHT(M23,2)))))) -> 45289 | P23: =IF(O23="","",IF(ISNUMBER(O23),O23,DATE(VALUE(LEFT(O23,4)),VALUE(MID(O23,6,2)),VALUE(RIGHT(O23,2))))) | R23: 0 | S23: 1 | T23: 21.3 | U23: ANZ | V23: 116146 | W23: =IF(E23="","",IF(E23="Closed Won","Won",IF(E23="Closed Lost","Lost","Open"))) -> Open | X23: =_xlfn.XLOOKUP(B23,'Customers'!A:A,'Customers'!E:E,"") -> Mid-Market | Y23: =IF(OR(W23="Won",W23="Lost"),1,0) -> 0 | Z23: =IF(OR(N23="",P23=""),"",P23-N23) | AA23: =IF(AND(Y23=1,Z23>30),1,0) -> 0
A24: DL-00023 | B24: CUST-0939 | D24: API Access | E24: Closed Lost | F24: $23,944 | G24: =IF(F24="","",IF(RIGHT(UPPER(SUBSTITUTE(SUBSTITUTE(SUBSTITUTE(TRIM(F24),"$",""),",","")," ","")),1)="K",VALUE(LEFT(UPPER(SUBSTITUTE(SUBSTITUTE(SUBSTITUTE(TRIM(F24),"$",""),",","")," ","")),LEN(UPPER(SUBSTITUTE(SUBSTITUTE(SUBSTITUTE(TRIM(F24),"$",""),",","")," ","")))-1))*1000,IF(RIGHT(UPPER(SUBSTITUTE(SUBSTITUTE(SUBSTITUTE(TRIM(F24),"$",""),",","")," ","")),1)="M",VALUE(LEFT(UPPER(SUBSTITUTE(SUBSTITUTE(SUBSTITUTE(TRIM(F24),"$",""),",","")," ","")),LEN(UPPER(SUBSTITUTE(SUBSTITUTE(SUBSTITUTE(TRIM(F24),"$",""),",","")," ","")))-1))*1000000,VALUE(SUBSTITUTE(SUBSTITUTE(SUBSTITUTE(TRIM(F24),"$",""),",","")," ",""))))) -> 23944 | H24: Cold Outreach | I24: Karan Karnik | J24: =PROPER(TRIM(I24)) -> Karan Karnik | K24: 2022-08-07 | L24: =IF(K24="","",IF(ISNUMBER(K24),K24,IF(ISNUMBER(SEARCH("/",K24)),DATE(VALUE(RIGHT(K24,4)),VALUE(MID(K24,4,2)),VALUE(LEFT(K24,2))),DATE(VALUE(LEFT(K24,4)),VALUE(MID(K24,6,2)),VALUE(RIGHT(K24,2)))))) -> 44780 | M24: 44944 | N24: =IF(M24="","",IF(ISNUMBER(M24),M24,IF(ISNUMBER(SEARCH("/",M24)),DATE(VALUE(RIGHT(M24,4)),VALUE(MID(M24,4,2)),VALUE(LEFT(M24,2))),DATE(VALUE(LEFT(M24,4)),VALUE(MID(M24,6,2)),VALUE(RIGHT(M24,2)))))) -> 44944 | O24: 44867 | P24: =IF(O24="","",IF(ISNUMBER(O24),O24,DATE(VALUE(LEFT(O24,4)),VALUE(MID(O24,6,2)),VALUE(RIGHT(O24,2))))) -> 44867 | Q24: 87 | R24: 0 | S24: 1 | U24: East Africa | V24: 23944 | W24: =IF(E24="","",IF(E24="Closed Won","Won",IF(E24="Closed Lost","Lost","Open"))) -> Lost | X24: =_xlfn.XLOOKUP(B24,'Customers'!A:A,'Customers'!E:E,"") -> SMB | Y24: =IF(OR(W24="Won",W24="Lost"),1,0) -> 1 | Z24: =IF(OR(N24="",P24=""),"",P24-N24) -> -77 | AA24: =IF(AND(Y24=1,Z24>30),1,0) -> 0
A25: DL-00024 | B25: CUST-0021 | C25: CMP-130 | D25: WorkHub Enterprise | E25: Closed Lost | F25: 115K | G25: =IF(F25="","",IF(RIGHT(UPPER(SUBSTITUTE(SUBSTITUTE(SUBSTITUTE(TRIM(F25),"$",""),",","")," ","")),1)="K",VALUE(LEFT(UPPER(SUBSTITUTE(SUBSTITUTE(SUBSTITUTE(TRIM(F25),"$",""),",","")," ","")),LEN(UPPER(SUBSTITUTE(SUBSTITUTE(SUBSTITUTE(TRIM(F25),"$",""),",","")," ","")))-1))*1000,IF(RIGHT(UPPER(SUBSTITUTE(SUBSTITUTE(SUBSTITUTE(TRIM(F25),"$",""),",","")," ","")),1)="M",VALUE(LEFT(UPPER(SUBSTITUTE(SUBSTITUTE(SUBSTITUTE(TRIM(F25),"$",""),",","")," ","")),LEN(UPPER(SUBSTITUTE(SUBSTITUTE(SUBSTITUTE(TRIM(F25),"$",""),",","")," ","")))-1))*1000000,VALUE(SUBSTITUTE(SUBSTITUTE(SUBSTITUTE(TRIM(F25),"$",""),",","")," ",""))))) -> 115000 | H25: Paid Search | I25: Amruta Sinha | J25: =PROPER(TRIM(I25)) -> Amruta Sinha | K25: 2024-03-23 | L25: =IF(K25="","",IF(ISNUMBER(K25),K25,IF(ISNUMBER(SEARCH("/",K25)),DATE(VALUE(RIGHT(K25,4)),VALUE(MID(K25,4,2)),VALUE(LEFT(K25,2))),DATE(VALUE(LEFT(K25,4)),VALUE(MID(K25,6,2)),VALUE(RIGHT(K25,2)))))) -> 45374 | N25: =IF(M25="","",IF(ISNUMBER(M25),M25,IF(ISNUMBER(SEARCH("/",M25)),DATE(VALUE(RIGHT(M25,4)),VALUE(MID(M25,4,2)),VALUE(LEFT(M25,2))),DATE(VALUE(LEFT(M25,4)),VALUE(MID(M25,6,2)),VALUE(RIGHT(M25,2)))))) | O25: 45533 | P25: =IF(O25="","",IF(ISNUMBER(O25),O25,DATE(VALUE(LEFT(O25,4)),VALUE(MID(O25,6,2)),VALUE(RIGHT(O25,2))))) -> 45533 | Q25: 159 | R25: 0 | S25: 1 | T25: 6.3 | U25: South Asia | V25: 115000 | W25: =IF(E25="","",IF(E25="Closed Won","Won",IF(E25="Closed Lost","Lost","Open"))) -> Lost | X25: =_xlfn.XLOOKUP(B25,'Customers'!A:A,'Customers'!E:E,"") -> SMB | Y25: =IF(OR(W25="Won",W25="Lost"),1,0) -> 1 | Z25: =IF(OR(N25="",P25=""),"",P25-N25) | AA25: =IF(AND(Y25=1,Z25>30),1,0) -> 1
